Backup failed for Site erp.srdc.io. Database or site_config.json may be corrupted
Traceback (most recent call last):
  File "apps/frappe/frappe/commands/site.py", line 718, in backup
    odb = scheduled_backup(
          ^^^^^^^^^^^^^^^^^
  File "apps/frappe/frappe/utils/backups.py", line 532, in scheduled_backup
    odb = new_backup(
          ^^^^^^^^^^^
  File "apps/frappe/frappe/utils/backups.py", line 566, in new_backup
    odb = BackupGenerator(
          ^^^^^^^^^^^^^^^^
  File "apps/frappe/frappe/utils/backups.py", line 84, in __init__
    self.setup_backup_tables()
  File "apps/frappe/frappe/utils/backups.py", line 116, in setup_backup_tables
    existing_tables = frappe.db.get_tables()
                      ^^^^^^^^^^^^^^^^^^^^^^
  File "apps/frappe/frappe/database/mariadb/database.py", line 442, in get_tables
    .run(pluck=True)
     ^^^^^^^^^^^^^^^
  File "apps/frappe/frappe/query_builder/utils.py", line 87, in execute_query
    result = frappe.db.sql(query, params, *args, **kwargs)  # nosemgrep
             ^^^^^^^^^^^^^^^^^^^^^^^^^^^^^^^^^^^^^^^^^^^^^
  File "apps/frappe/frappe/database/database.py", line 201, in sql
    self.connect()
  File "apps/frappe/frappe/database/database.py", line 115, in connect
    self._conn = self.get_connection()
                 ^^^^^^^^^^^^^^^^^^^^^
  File "apps/frappe/frappe/database/mariadb/database.py", line 98, in get_connection
    conn = self._get_connection()
           ^^^^^^^^^^^^^^^^^^^^^^
  File "apps/frappe/frappe/database/mariadb/database.py", line 104, in _get_connection
    return self.create_connection()
           ^^^^^^^^^^^^^^^^^^^^^^^^
  File "apps/frappe/frappe/database/mariadb/database.py", line 107, in create_connection
    return pymysql.connect(**self.get_connection_settings())
           ^^^^^^^^^^^^^^^^^^^^^^^^^^^^^^^^^^^^^^^^^^^^^^^^^
  File "env/lib/python3.11/site-packages/pymysql/connections.py", line 352, in __init__
    self.connect()
  File "env/lib/python3.11/site-packages/pymysql/connections.py", line 636, in connect
    self._request_authentication()
  File "env/lib/python3.11/site-packages/pymysql/connections.py", line 911, in _request_authentication
    auth_packet = self._read_packet()
                  ^^^^^^^^^^^^^^^^^^^
  File "env/lib/python3.11/site-packages/pymysql/connections.py", line 729, in _read_packet
    packet.raise_for_error()
  File "env/lib/python3.11/site-packages/pymysql/protocol.py", line 221, in raise_for_error
    err.raise_mysql_exception(self._data)
  File "env/lib/python3.11/site-packages/pymysql/err.py", line 143, in raise_mysql_exception
    raise errorclass(errno, errval)
pymysql.err.OperationalError: (1045, "Access denied for user '_9b8e683170b398ec'@'localhost' (using password: YES)")

Backup failed for Site erp.srdc.io. Database or site_config.json may be corrupted
Traceback (most recent call last):
  File "apps/frappe/frappe/commands/site.py", line 718, in backup
    odb = scheduled_backup(
          ^^^^^^^^^^^^^^^^^
  File "apps/frappe/frappe/utils/backups.py", line 532, in scheduled_backup
    odb = new_backup(
          ^^^^^^^^^^^
  File "apps/frappe/frappe/utils/backups.py", line 566, in new_backup
    odb = BackupGenerator(
          ^^^^^^^^^^^^^^^^
  File "apps/frappe/frappe/utils/backups.py", line 84, in __init__
    self.setup_backup_tables()
  File "apps/frappe/frappe/utils/backups.py", line 116, in setup_backup_tables
    existing_tables = frappe.db.get_tables()
                      ^^^^^^^^^^^^^^^^^^^^^^
  File "apps/frappe/frappe/database/mariadb/database.py", line 442, in get_tables
    .run(pluck=True)
     ^^^^^^^^^^^^^^^
  File "apps/frappe/frappe/query_builder/utils.py", line 87, in execute_query
    result = frappe.db.sql(query, params, *args, **kwargs)  # nosemgrep
             ^^^^^^^^^^^^^^^^^^^^^^^^^^^^^^^^^^^^^^^^^^^^^
  File "apps/frappe/frappe/database/database.py", line 201, in sql
    self.connect()
  File "apps/frappe/frappe/database/database.py", line 115, in connect
    self._conn = self.get_connection()
                 ^^^^^^^^^^^^^^^^^^^^^
  File "apps/frappe/frappe/database/mariadb/database.py", line 98, in get_connection
    conn = self._get_connection()
           ^^^^^^^^^^^^^^^^^^^^^^
  File "apps/frappe/frappe/database/mariadb/database.py", line 104, in _get_connection
    return self.create_connection()
           ^^^^^^^^^^^^^^^^^^^^^^^^
  File "apps/frappe/frappe/database/mariadb/database.py", line 107, in create_connection
    return pymysql.connect(**self.get_connection_settings())
           ^^^^^^^^^^^^^^^^^^^^^^^^^^^^^^^^^^^^^^^^^^^^^^^^^
  File "env/lib/python3.11/site-packages/pymysql/connections.py", line 352, in __init__
    self.connect()
  File "env/lib/python3.11/site-packages/pymysql/connections.py", line 636, in connect
    self._request_authentication()
  File "env/lib/python3.11/site-packages/pymysql/connections.py", line 911, in _request_authentication
    auth_packet = self._read_packet()
                  ^^^^^^^^^^^^^^^^^^^
  File "env/lib/python3.11/site-packages/pymysql/connections.py", line 729, in _read_packet
    packet.raise_for_error()
  File "env/lib/python3.11/site-packages/pymysql/protocol.py", line 221, in raise_for_error
    err.raise_mysql_exception(self._data)
  File "env/lib/python3.11/site-packages/pymysql/err.py", line 143, in raise_mysql_exception
    raise errorclass(errno, errval)
pymysql.err.OperationalError: (1049, "Unknown database '_9b8e683170b398ec'")

Backup failed for Site srdc.local. Database or site_config.json may be corrupted
Traceback (most recent call last):
  File "apps/frappe/frappe/commands/site.py", line 718, in backup
    odb = scheduled_backup(
          ^^^^^^^^^^^^^^^^^
  File "apps/frappe/frappe/utils/backups.py", line 532, in scheduled_backup
    odb = new_backup(
          ^^^^^^^^^^^
  File "apps/frappe/frappe/utils/backups.py", line 566, in new_backup
    odb = BackupGenerator(
          ^^^^^^^^^^^^^^^^
  File "apps/frappe/frappe/utils/backups.py", line 84, in __init__
    self.setup_backup_tables()
  File "apps/frappe/frappe/utils/backups.py", line 116, in setup_backup_tables
    existing_tables = frappe.db.get_tables()
                      ^^^^^^^^^^^^^^^^^^^^^^
  File "apps/frappe/frappe/database/mariadb/database.py", line 442, in get_tables
    .run(pluck=True)
     ^^^^^^^^^^^^^^^
  File "apps/frappe/frappe/query_builder/utils.py", line 87, in execute_query
    result = frappe.db.sql(query, params, *args, **kwargs)  # nosemgrep
             ^^^^^^^^^^^^^^^^^^^^^^^^^^^^^^^^^^^^^^^^^^^^^
  File "apps/frappe/frappe/database/database.py", line 201, in sql
    self.connect()
  File "apps/frappe/frappe/database/database.py", line 115, in connect
    self._conn = self.get_connection()
                 ^^^^^^^^^^^^^^^^^^^^^
  File "apps/frappe/frappe/database/mariadb/database.py", line 98, in get_connection
    conn = self._get_connection()
           ^^^^^^^^^^^^^^^^^^^^^^
  File "apps/frappe/frappe/database/mariadb/database.py", line 104, in _get_connection
    return self.create_connection()
           ^^^^^^^^^^^^^^^^^^^^^^^^
  File "apps/frappe/frappe/database/mariadb/database.py", line 107, in create_connection
    return pymysql.connect(**self.get_connection_settings())
           ^^^^^^^^^^^^^^^^^^^^^^^^^^^^^^^^^^^^^^^^^^^^^^^^^
  File "env/lib/python3.11/site-packages/pymysql/connections.py", line 352, in __init__
    self.connect()
  File "env/lib/python3.11/site-packages/pymysql/connections.py", line 636, in connect
    self._request_authentication()
  File "env/lib/python3.11/site-packages/pymysql/connections.py", line 911, in _request_authentication
    auth_packet = self._read_packet()
                  ^^^^^^^^^^^^^^^^^^^
  File "env/lib/python3.11/site-packages/pymysql/connections.py", line 729, in _read_packet
    packet.raise_for_error()
  File "env/lib/python3.11/site-packages/pymysql/protocol.py", line 221, in raise_for_error
    err.raise_mysql_exception(self._data)
  File "env/lib/python3.11/site-packages/pymysql/err.py", line 143, in raise_mysql_exception
    raise errorclass(errno, errval)
pymysql.err.OperationalError: (1049, "Unknown database '_9b8e683170b398ec'")

self=$$;  ( mysqldump --single-transaction --quick --lock-tables=false -u _9b8e683170b398ec -p********** _9b8e683170b398ec -h 127.0.0.1 -P 3306   || kill $self )  | /usr/bin/gzip >> ./erp.srdc.io/private/backups/20231114_180002-erp_srdc_io-database.sql.gz

Backup Summary for erp.srdc.io at 2023-11-14 18:00:03.085155
Config  : ./erp.srdc.io/private/backups/20231114_180002-erp_srdc_io-site_config_backup.json 94.0B
Database: ./erp.srdc.io/private/backups/20231114_180002-erp_srdc_io-database.sql.gz         264.6KiB
Backup for Site erp.srdc.io has been successfully completed
self=$$;  ( mysqldump --single-transaction --quick --lock-tables=false -u _9b8e683170b398ec -p********** _9b8e683170b398ec -h 127.0.0.1 -P 3306   || kill $self )  | /usr/bin/gzip >> ./erp.srdc.io/private/backups/20231115_120002-erp_srdc_io-database.sql.gz

Backup Summary for erp.srdc.io at 2023-11-15 12:00:02.681137
Config  : ./erp.srdc.io/private/backups/20231115_120002-erp_srdc_io-site_config_backup.json 150.0B
Database: ./erp.srdc.io/private/backups/20231115_120002-erp_srdc_io-database.sql.gz         267.6KiB
Backup for Site erp.srdc.io has been successfully completed
