2023-11-14 10:57:54,902 ERROR scheduler Exception in Enqueue Events for Site srdc.local
Traceback (most recent call last):
  File "apps/frappe/frappe/utils/scheduler.py", line 75, in enqueue_events_for_site
    if is_scheduler_inactive():
       ^^^^^^^^^^^^^^^^^^^^^^^
  File "apps/frappe/frappe/utils/scheduler.py", line 114, in is_scheduler_inactive
    if is_scheduler_disabled(verbose=verbose):
       ^^^^^^^^^^^^^^^^^^^^^^^^^^^^^^^^^^^^^^
  File "apps/frappe/frappe/utils/scheduler.py", line 127, in is_scheduler_disabled
    frappe.db.get_single_value("System Settings", "enable_scheduler")
  File "apps/frappe/frappe/database/database.py", line 786, in get_single_value
    ).run()
      ^^^^^
  File "apps/frappe/frappe/query_builder/utils.py", line 87, in execute_query
    result = frappe.db.sql(query, params, *args, **kwargs)  # nosemgrep
             ^^^^^^^^^^^^^^^^^^^^^^^^^^^^^^^^^^^^^^^^^^^^^
  File "apps/frappe/frappe/database/database.py", line 201, in sql
    self.connect()
  File "apps/frappe/frappe/database/database.py", line 115, in connect
    self._conn = self.get_connection()
                 ^^^^^^^^^^^^^^^^^^^^^
  File "apps/frappe/frappe/database/mariadb/database.py", line 98, in get_connection
    conn = self._get_connection()
           ^^^^^^^^^^^^^^^^^^^^^^
  File "apps/frappe/frappe/database/mariadb/database.py", line 104, in _get_connection
    return self.create_connection()
           ^^^^^^^^^^^^^^^^^^^^^^^^
  File "apps/frappe/frappe/database/mariadb/database.py", line 107, in create_connection
    return pymysql.connect(**self.get_connection_settings())
           ^^^^^^^^^^^^^^^^^^^^^^^^^^^^^^^^^^^^^^^^^^^^^^^^^
  File "env/lib/python3.11/site-packages/pymysql/connections.py", line 352, in __init__
    self.connect()
  File "env/lib/python3.11/site-packages/pymysql/connections.py", line 636, in connect
    self._request_authentication()
  File "env/lib/python3.11/site-packages/pymysql/connections.py", line 911, in _request_authentication
    auth_packet = self._read_packet()
                  ^^^^^^^^^^^^^^^^^^^
  File "env/lib/python3.11/site-packages/pymysql/connections.py", line 729, in _read_packet
    packet.raise_for_error()
  File "env/lib/python3.11/site-packages/pymysql/protocol.py", line 221, in raise_for_error
    err.raise_mysql_exception(self._data)
  File "env/lib/python3.11/site-packages/pymysql/err.py", line 143, in raise_mysql_exception
    raise errorclass(errno, errval)
pymysql.err.OperationalError: (1049, "Unknown database '_3f14d08a0477f193'")

2023-11-14 10:57:54,904 ERROR scheduler Exception in Enqueue Events for Site erp.srdc.io
Traceback (most recent call last):
  File "apps/frappe/frappe/utils/scheduler.py", line 75, in enqueue_events_for_site
    if is_scheduler_inactive():
       ^^^^^^^^^^^^^^^^^^^^^^^
  File "apps/frappe/frappe/utils/scheduler.py", line 114, in is_scheduler_inactive
    if is_scheduler_disabled(verbose=verbose):
       ^^^^^^^^^^^^^^^^^^^^^^^^^^^^^^^^^^^^^^
  File "apps/frappe/frappe/utils/scheduler.py", line 127, in is_scheduler_disabled
    frappe.db.get_single_value("System Settings", "enable_scheduler")
  File "apps/frappe/frappe/database/database.py", line 786, in get_single_value
    ).run()
      ^^^^^
  File "apps/frappe/frappe/query_builder/utils.py", line 87, in execute_query
    result = frappe.db.sql(query, params, *args, **kwargs)  # nosemgrep
             ^^^^^^^^^^^^^^^^^^^^^^^^^^^^^^^^^^^^^^^^^^^^^
  File "apps/frappe/frappe/database/database.py", line 201, in sql
    self.connect()
  File "apps/frappe/frappe/database/database.py", line 115, in connect
    self._conn = self.get_connection()
                 ^^^^^^^^^^^^^^^^^^^^^
  File "apps/frappe/frappe/database/mariadb/database.py", line 98, in get_connection
    conn = self._get_connection()
           ^^^^^^^^^^^^^^^^^^^^^^
  File "apps/frappe/frappe/database/mariadb/database.py", line 104, in _get_connection
    return self.create_connection()
           ^^^^^^^^^^^^^^^^^^^^^^^^
  File "apps/frappe/frappe/database/mariadb/database.py", line 107, in create_connection
    return pymysql.connect(**self.get_connection_settings())
           ^^^^^^^^^^^^^^^^^^^^^^^^^^^^^^^^^^^^^^^^^^^^^^^^^
  File "env/lib/python3.11/site-packages/pymysql/connections.py", line 352, in __init__
    self.connect()
  File "env/lib/python3.11/site-packages/pymysql/connections.py", line 636, in connect
    self._request_authentication()
  File "env/lib/python3.11/site-packages/pymysql/connections.py", line 911, in _request_authentication
    auth_packet = self._read_packet()
                  ^^^^^^^^^^^^^^^^^^^
  File "env/lib/python3.11/site-packages/pymysql/connections.py", line 729, in _read_packet
    packet.raise_for_error()
  File "env/lib/python3.11/site-packages/pymysql/protocol.py", line 221, in raise_for_error
    err.raise_mysql_exception(self._data)
  File "env/lib/python3.11/site-packages/pymysql/err.py", line 143, in raise_mysql_exception
    raise errorclass(errno, errval)
pymysql.err.OperationalError: (1049, "Unknown database '_9b8e683170b398ec'")

2023-11-14 10:58:54,920 ERROR scheduler Exception in Enqueue Events for Site erp.srdc.io
Traceback (most recent call last):
  File "apps/frappe/frappe/utils/scheduler.py", line 75, in enqueue_events_for_site
    if is_scheduler_inactive():
       ^^^^^^^^^^^^^^^^^^^^^^^
  File "apps/frappe/frappe/utils/scheduler.py", line 114, in is_scheduler_inactive
    if is_scheduler_disabled(verbose=verbose):
       ^^^^^^^^^^^^^^^^^^^^^^^^^^^^^^^^^^^^^^
  File "apps/frappe/frappe/utils/scheduler.py", line 127, in is_scheduler_disabled
    frappe.db.get_single_value("System Settings", "enable_scheduler")
  File "apps/frappe/frappe/database/database.py", line 786, in get_single_value
    ).run()
      ^^^^^
  File "apps/frappe/frappe/query_builder/utils.py", line 87, in execute_query
    result = frappe.db.sql(query, params, *args, **kwargs)  # nosemgrep
             ^^^^^^^^^^^^^^^^^^^^^^^^^^^^^^^^^^^^^^^^^^^^^
  File "apps/frappe/frappe/database/database.py", line 201, in sql
    self.connect()
  File "apps/frappe/frappe/database/database.py", line 115, in connect
    self._conn = self.get_connection()
                 ^^^^^^^^^^^^^^^^^^^^^
  File "apps/frappe/frappe/database/mariadb/database.py", line 98, in get_connection
    conn = self._get_connection()
           ^^^^^^^^^^^^^^^^^^^^^^
  File "apps/frappe/frappe/database/mariadb/database.py", line 104, in _get_connection
    return self.create_connection()
           ^^^^^^^^^^^^^^^^^^^^^^^^
  File "apps/frappe/frappe/database/mariadb/database.py", line 107, in create_connection
    return pymysql.connect(**self.get_connection_settings())
           ^^^^^^^^^^^^^^^^^^^^^^^^^^^^^^^^^^^^^^^^^^^^^^^^^
  File "env/lib/python3.11/site-packages/pymysql/connections.py", line 352, in __init__
    self.connect()
  File "env/lib/python3.11/site-packages/pymysql/connections.py", line 636, in connect
    self._request_authentication()
  File "env/lib/python3.11/site-packages/pymysql/connections.py", line 911, in _request_authentication
    auth_packet = self._read_packet()
                  ^^^^^^^^^^^^^^^^^^^
  File "env/lib/python3.11/site-packages/pymysql/connections.py", line 729, in _read_packet
    packet.raise_for_error()
  File "env/lib/python3.11/site-packages/pymysql/protocol.py", line 221, in raise_for_error
    err.raise_mysql_exception(self._data)
  File "env/lib/python3.11/site-packages/pymysql/err.py", line 143, in raise_mysql_exception
    raise errorclass(errno, errval)
pymysql.err.OperationalError: (1049, "Unknown database '_9b8e683170b398ec'")

2023-11-14 10:58:54,925 ERROR scheduler Exception in Enqueue Events for Site srdc.local
Traceback (most recent call last):
  File "apps/frappe/frappe/utils/scheduler.py", line 75, in enqueue_events_for_site
    if is_scheduler_inactive():
       ^^^^^^^^^^^^^^^^^^^^^^^
  File "apps/frappe/frappe/utils/scheduler.py", line 114, in is_scheduler_inactive
    if is_scheduler_disabled(verbose=verbose):
       ^^^^^^^^^^^^^^^^^^^^^^^^^^^^^^^^^^^^^^
  File "apps/frappe/frappe/utils/scheduler.py", line 127, in is_scheduler_disabled
    frappe.db.get_single_value("System Settings", "enable_scheduler")
  File "apps/frappe/frappe/database/database.py", line 786, in get_single_value
    ).run()
      ^^^^^
  File "apps/frappe/frappe/query_builder/utils.py", line 87, in execute_query
    result = frappe.db.sql(query, params, *args, **kwargs)  # nosemgrep
             ^^^^^^^^^^^^^^^^^^^^^^^^^^^^^^^^^^^^^^^^^^^^^
  File "apps/frappe/frappe/database/database.py", line 201, in sql
    self.connect()
  File "apps/frappe/frappe/database/database.py", line 115, in connect
    self._conn = self.get_connection()
                 ^^^^^^^^^^^^^^^^^^^^^
  File "apps/frappe/frappe/database/mariadb/database.py", line 98, in get_connection
    conn = self._get_connection()
           ^^^^^^^^^^^^^^^^^^^^^^
  File "apps/frappe/frappe/database/mariadb/database.py", line 104, in _get_connection
    return self.create_connection()
           ^^^^^^^^^^^^^^^^^^^^^^^^
  File "apps/frappe/frappe/database/mariadb/database.py", line 107, in create_connection
    return pymysql.connect(**self.get_connection_settings())
           ^^^^^^^^^^^^^^^^^^^^^^^^^^^^^^^^^^^^^^^^^^^^^^^^^
  File "env/lib/python3.11/site-packages/pymysql/connections.py", line 352, in __init__
    self.connect()
  File "env/lib/python3.11/site-packages/pymysql/connections.py", line 636, in connect
    self._request_authentication()
  File "env/lib/python3.11/site-packages/pymysql/connections.py", line 911, in _request_authentication
    auth_packet = self._read_packet()
                  ^^^^^^^^^^^^^^^^^^^
  File "env/lib/python3.11/site-packages/pymysql/connections.py", line 729, in _read_packet
    packet.raise_for_error()
  File "env/lib/python3.11/site-packages/pymysql/protocol.py", line 221, in raise_for_error
    err.raise_mysql_exception(self._data)
  File "env/lib/python3.11/site-packages/pymysql/err.py", line 143, in raise_mysql_exception
    raise errorclass(errno, errval)
pymysql.err.OperationalError: (1049, "Unknown database '_3f14d08a0477f193'")

2023-11-14 10:59:54,942 ERROR scheduler Exception in Enqueue Events for Site erp.srdc.io
Traceback (most recent call last):
  File "apps/frappe/frappe/utils/scheduler.py", line 75, in enqueue_events_for_site
    if is_scheduler_inactive():
       ^^^^^^^^^^^^^^^^^^^^^^^
  File "apps/frappe/frappe/utils/scheduler.py", line 114, in is_scheduler_inactive
    if is_scheduler_disabled(verbose=verbose):
       ^^^^^^^^^^^^^^^^^^^^^^^^^^^^^^^^^^^^^^
  File "apps/frappe/frappe/utils/scheduler.py", line 127, in is_scheduler_disabled
    frappe.db.get_single_value("System Settings", "enable_scheduler")
  File "apps/frappe/frappe/database/database.py", line 786, in get_single_value
    ).run()
      ^^^^^
  File "apps/frappe/frappe/query_builder/utils.py", line 87, in execute_query
    result = frappe.db.sql(query, params, *args, **kwargs)  # nosemgrep
             ^^^^^^^^^^^^^^^^^^^^^^^^^^^^^^^^^^^^^^^^^^^^^
  File "apps/frappe/frappe/database/database.py", line 201, in sql
    self.connect()
  File "apps/frappe/frappe/database/database.py", line 115, in connect
    self._conn = self.get_connection()
                 ^^^^^^^^^^^^^^^^^^^^^
  File "apps/frappe/frappe/database/mariadb/database.py", line 98, in get_connection
    conn = self._get_connection()
           ^^^^^^^^^^^^^^^^^^^^^^
  File "apps/frappe/frappe/database/mariadb/database.py", line 104, in _get_connection
    return self.create_connection()
           ^^^^^^^^^^^^^^^^^^^^^^^^
  File "apps/frappe/frappe/database/mariadb/database.py", line 107, in create_connection
    return pymysql.connect(**self.get_connection_settings())
           ^^^^^^^^^^^^^^^^^^^^^^^^^^^^^^^^^^^^^^^^^^^^^^^^^
  File "env/lib/python3.11/site-packages/pymysql/connections.py", line 352, in __init__
    self.connect()
  File "env/lib/python3.11/site-packages/pymysql/connections.py", line 636, in connect
    self._request_authentication()
  File "env/lib/python3.11/site-packages/pymysql/connections.py", line 911, in _request_authentication
    auth_packet = self._read_packet()
                  ^^^^^^^^^^^^^^^^^^^
  File "env/lib/python3.11/site-packages/pymysql/connections.py", line 729, in _read_packet
    packet.raise_for_error()
  File "env/lib/python3.11/site-packages/pymysql/protocol.py", line 221, in raise_for_error
    err.raise_mysql_exception(self._data)
  File "env/lib/python3.11/site-packages/pymysql/err.py", line 143, in raise_mysql_exception
    raise errorclass(errno, errval)
pymysql.err.OperationalError: (1049, "Unknown database '_9b8e683170b398ec'")

2023-11-14 10:59:54,947 ERROR scheduler Exception in Enqueue Events for Site srdc.local
Traceback (most recent call last):
  File "apps/frappe/frappe/utils/scheduler.py", line 75, in enqueue_events_for_site
    if is_scheduler_inactive():
       ^^^^^^^^^^^^^^^^^^^^^^^
  File "apps/frappe/frappe/utils/scheduler.py", line 114, in is_scheduler_inactive
    if is_scheduler_disabled(verbose=verbose):
       ^^^^^^^^^^^^^^^^^^^^^^^^^^^^^^^^^^^^^^
  File "apps/frappe/frappe/utils/scheduler.py", line 127, in is_scheduler_disabled
    frappe.db.get_single_value("System Settings", "enable_scheduler")
  File "apps/frappe/frappe/database/database.py", line 786, in get_single_value
    ).run()
      ^^^^^
  File "apps/frappe/frappe/query_builder/utils.py", line 87, in execute_query
    result = frappe.db.sql(query, params, *args, **kwargs)  # nosemgrep
             ^^^^^^^^^^^^^^^^^^^^^^^^^^^^^^^^^^^^^^^^^^^^^
  File "apps/frappe/frappe/database/database.py", line 201, in sql
    self.connect()
  File "apps/frappe/frappe/database/database.py", line 115, in connect
    self._conn = self.get_connection()
                 ^^^^^^^^^^^^^^^^^^^^^
  File "apps/frappe/frappe/database/mariadb/database.py", line 98, in get_connection
    conn = self._get_connection()
           ^^^^^^^^^^^^^^^^^^^^^^
  File "apps/frappe/frappe/database/mariadb/database.py", line 104, in _get_connection
    return self.create_connection()
           ^^^^^^^^^^^^^^^^^^^^^^^^
  File "apps/frappe/frappe/database/mariadb/database.py", line 107, in create_connection
    return pymysql.connect(**self.get_connection_settings())
           ^^^^^^^^^^^^^^^^^^^^^^^^^^^^^^^^^^^^^^^^^^^^^^^^^
  File "env/lib/python3.11/site-packages/pymysql/connections.py", line 352, in __init__
    self.connect()
  File "env/lib/python3.11/site-packages/pymysql/connections.py", line 636, in connect
    self._request_authentication()
  File "env/lib/python3.11/site-packages/pymysql/connections.py", line 911, in _request_authentication
    auth_packet = self._read_packet()
                  ^^^^^^^^^^^^^^^^^^^
  File "env/lib/python3.11/site-packages/pymysql/connections.py", line 729, in _read_packet
    packet.raise_for_error()
  File "env/lib/python3.11/site-packages/pymysql/protocol.py", line 221, in raise_for_error
    err.raise_mysql_exception(self._data)
  File "env/lib/python3.11/site-packages/pymysql/err.py", line 143, in raise_mysql_exception
    raise errorclass(errno, errval)
pymysql.err.OperationalError: (1049, "Unknown database '_3f14d08a0477f193'")

2023-11-14 11:00:54,962 ERROR scheduler Exception in Enqueue Events for Site srdc.local
Traceback (most recent call last):
  File "apps/frappe/frappe/utils/scheduler.py", line 75, in enqueue_events_for_site
    if is_scheduler_inactive():
       ^^^^^^^^^^^^^^^^^^^^^^^
  File "apps/frappe/frappe/utils/scheduler.py", line 114, in is_scheduler_inactive
    if is_scheduler_disabled(verbose=verbose):
       ^^^^^^^^^^^^^^^^^^^^^^^^^^^^^^^^^^^^^^
  File "apps/frappe/frappe/utils/scheduler.py", line 127, in is_scheduler_disabled
    frappe.db.get_single_value("System Settings", "enable_scheduler")
  File "apps/frappe/frappe/database/database.py", line 786, in get_single_value
    ).run()
      ^^^^^
  File "apps/frappe/frappe/query_builder/utils.py", line 87, in execute_query
    result = frappe.db.sql(query, params, *args, **kwargs)  # nosemgrep
             ^^^^^^^^^^^^^^^^^^^^^^^^^^^^^^^^^^^^^^^^^^^^^
  File "apps/frappe/frappe/database/database.py", line 201, in sql
    self.connect()
  File "apps/frappe/frappe/database/database.py", line 115, in connect
    self._conn = self.get_connection()
                 ^^^^^^^^^^^^^^^^^^^^^
  File "apps/frappe/frappe/database/mariadb/database.py", line 98, in get_connection
    conn = self._get_connection()
           ^^^^^^^^^^^^^^^^^^^^^^
  File "apps/frappe/frappe/database/mariadb/database.py", line 104, in _get_connection
    return self.create_connection()
           ^^^^^^^^^^^^^^^^^^^^^^^^
  File "apps/frappe/frappe/database/mariadb/database.py", line 107, in create_connection
    return pymysql.connect(**self.get_connection_settings())
           ^^^^^^^^^^^^^^^^^^^^^^^^^^^^^^^^^^^^^^^^^^^^^^^^^
  File "env/lib/python3.11/site-packages/pymysql/connections.py", line 352, in __init__
    self.connect()
  File "env/lib/python3.11/site-packages/pymysql/connections.py", line 636, in connect
    self._request_authentication()
  File "env/lib/python3.11/site-packages/pymysql/connections.py", line 911, in _request_authentication
    auth_packet = self._read_packet()
                  ^^^^^^^^^^^^^^^^^^^
  File "env/lib/python3.11/site-packages/pymysql/connections.py", line 729, in _read_packet
    packet.raise_for_error()
  File "env/lib/python3.11/site-packages/pymysql/protocol.py", line 221, in raise_for_error
    err.raise_mysql_exception(self._data)
  File "env/lib/python3.11/site-packages/pymysql/err.py", line 143, in raise_mysql_exception
    raise errorclass(errno, errval)
pymysql.err.OperationalError: (1049, "Unknown database '_3f14d08a0477f193'")

2023-11-14 11:00:54,971 ERROR scheduler Exception in Enqueue Events for Site erp.srdc.io
Traceback (most recent call last):
  File "apps/frappe/frappe/utils/scheduler.py", line 75, in enqueue_events_for_site
    if is_scheduler_inactive():
       ^^^^^^^^^^^^^^^^^^^^^^^
  File "apps/frappe/frappe/utils/scheduler.py", line 114, in is_scheduler_inactive
    if is_scheduler_disabled(verbose=verbose):
       ^^^^^^^^^^^^^^^^^^^^^^^^^^^^^^^^^^^^^^
  File "apps/frappe/frappe/utils/scheduler.py", line 127, in is_scheduler_disabled
    frappe.db.get_single_value("System Settings", "enable_scheduler")
  File "apps/frappe/frappe/database/database.py", line 786, in get_single_value
    ).run()
      ^^^^^
  File "apps/frappe/frappe/query_builder/utils.py", line 87, in execute_query
    result = frappe.db.sql(query, params, *args, **kwargs)  # nosemgrep
             ^^^^^^^^^^^^^^^^^^^^^^^^^^^^^^^^^^^^^^^^^^^^^
  File "apps/frappe/frappe/database/database.py", line 201, in sql
    self.connect()
  File "apps/frappe/frappe/database/database.py", line 115, in connect
    self._conn = self.get_connection()
                 ^^^^^^^^^^^^^^^^^^^^^
  File "apps/frappe/frappe/database/mariadb/database.py", line 98, in get_connection
    conn = self._get_connection()
           ^^^^^^^^^^^^^^^^^^^^^^
  File "apps/frappe/frappe/database/mariadb/database.py", line 104, in _get_connection
    return self.create_connection()
           ^^^^^^^^^^^^^^^^^^^^^^^^
  File "apps/frappe/frappe/database/mariadb/database.py", line 107, in create_connection
    return pymysql.connect(**self.get_connection_settings())
           ^^^^^^^^^^^^^^^^^^^^^^^^^^^^^^^^^^^^^^^^^^^^^^^^^
  File "env/lib/python3.11/site-packages/pymysql/connections.py", line 352, in __init__
    self.connect()
  File "env/lib/python3.11/site-packages/pymysql/connections.py", line 636, in connect
    self._request_authentication()
  File "env/lib/python3.11/site-packages/pymysql/connections.py", line 911, in _request_authentication
    auth_packet = self._read_packet()
                  ^^^^^^^^^^^^^^^^^^^
  File "env/lib/python3.11/site-packages/pymysql/connections.py", line 729, in _read_packet
    packet.raise_for_error()
  File "env/lib/python3.11/site-packages/pymysql/protocol.py", line 221, in raise_for_error
    err.raise_mysql_exception(self._data)
  File "env/lib/python3.11/site-packages/pymysql/err.py", line 143, in raise_mysql_exception
    raise errorclass(errno, errval)
pymysql.err.OperationalError: (1049, "Unknown database '_9b8e683170b398ec'")

2023-11-14 11:03:52,245 ERROR scheduler Exception in Enqueue Events for Site erp.srdc.io
Traceback (most recent call last):
  File "apps/frappe/frappe/utils/scheduler.py", line 75, in enqueue_events_for_site
    if is_scheduler_inactive():
       ^^^^^^^^^^^^^^^^^^^^^^^
  File "apps/frappe/frappe/utils/scheduler.py", line 114, in is_scheduler_inactive
    if is_scheduler_disabled(verbose=verbose):
       ^^^^^^^^^^^^^^^^^^^^^^^^^^^^^^^^^^^^^^
  File "apps/frappe/frappe/utils/scheduler.py", line 127, in is_scheduler_disabled
    frappe.db.get_single_value("System Settings", "enable_scheduler")
  File "apps/frappe/frappe/database/database.py", line 786, in get_single_value
    ).run()
      ^^^^^
  File "apps/frappe/frappe/query_builder/utils.py", line 87, in execute_query
    result = frappe.db.sql(query, params, *args, **kwargs)  # nosemgrep
             ^^^^^^^^^^^^^^^^^^^^^^^^^^^^^^^^^^^^^^^^^^^^^
  File "apps/frappe/frappe/database/database.py", line 201, in sql
    self.connect()
  File "apps/frappe/frappe/database/database.py", line 115, in connect
    self._conn = self.get_connection()
                 ^^^^^^^^^^^^^^^^^^^^^
  File "apps/frappe/frappe/database/mariadb/database.py", line 98, in get_connection
    conn = self._get_connection()
           ^^^^^^^^^^^^^^^^^^^^^^
  File "apps/frappe/frappe/database/mariadb/database.py", line 104, in _get_connection
    return self.create_connection()
           ^^^^^^^^^^^^^^^^^^^^^^^^
  File "apps/frappe/frappe/database/mariadb/database.py", line 107, in create_connection
    return pymysql.connect(**self.get_connection_settings())
           ^^^^^^^^^^^^^^^^^^^^^^^^^^^^^^^^^^^^^^^^^^^^^^^^^
  File "env/lib/python3.11/site-packages/pymysql/connections.py", line 352, in __init__
    self.connect()
  File "env/lib/python3.11/site-packages/pymysql/connections.py", line 636, in connect
    self._request_authentication()
  File "env/lib/python3.11/site-packages/pymysql/connections.py", line 911, in _request_authentication
    auth_packet = self._read_packet()
                  ^^^^^^^^^^^^^^^^^^^
  File "env/lib/python3.11/site-packages/pymysql/connections.py", line 729, in _read_packet
    packet.raise_for_error()
  File "env/lib/python3.11/site-packages/pymysql/protocol.py", line 221, in raise_for_error
    err.raise_mysql_exception(self._data)
  File "env/lib/python3.11/site-packages/pymysql/err.py", line 143, in raise_mysql_exception
    raise errorclass(errno, errval)
pymysql.err.OperationalError: (1049, "Unknown database '_9b8e683170b398ec'")

2023-11-14 11:03:52,247 ERROR scheduler Exception in Enqueue Events for Site srdc.local
Traceback (most recent call last):
  File "apps/frappe/frappe/utils/scheduler.py", line 75, in enqueue_events_for_site
    if is_scheduler_inactive():
       ^^^^^^^^^^^^^^^^^^^^^^^
  File "apps/frappe/frappe/utils/scheduler.py", line 114, in is_scheduler_inactive
    if is_scheduler_disabled(verbose=verbose):
       ^^^^^^^^^^^^^^^^^^^^^^^^^^^^^^^^^^^^^^
  File "apps/frappe/frappe/utils/scheduler.py", line 127, in is_scheduler_disabled
    frappe.db.get_single_value("System Settings", "enable_scheduler")
  File "apps/frappe/frappe/database/database.py", line 786, in get_single_value
    ).run()
      ^^^^^
  File "apps/frappe/frappe/query_builder/utils.py", line 87, in execute_query
    result = frappe.db.sql(query, params, *args, **kwargs)  # nosemgrep
             ^^^^^^^^^^^^^^^^^^^^^^^^^^^^^^^^^^^^^^^^^^^^^
  File "apps/frappe/frappe/database/database.py", line 201, in sql
    self.connect()
  File "apps/frappe/frappe/database/database.py", line 115, in connect
    self._conn = self.get_connection()
                 ^^^^^^^^^^^^^^^^^^^^^
  File "apps/frappe/frappe/database/mariadb/database.py", line 98, in get_connection
    conn = self._get_connection()
           ^^^^^^^^^^^^^^^^^^^^^^
  File "apps/frappe/frappe/database/mariadb/database.py", line 104, in _get_connection
    return self.create_connection()
           ^^^^^^^^^^^^^^^^^^^^^^^^
  File "apps/frappe/frappe/database/mariadb/database.py", line 107, in create_connection
    return pymysql.connect(**self.get_connection_settings())
           ^^^^^^^^^^^^^^^^^^^^^^^^^^^^^^^^^^^^^^^^^^^^^^^^^
  File "env/lib/python3.11/site-packages/pymysql/connections.py", line 352, in __init__
    self.connect()
  File "env/lib/python3.11/site-packages/pymysql/connections.py", line 636, in connect
    self._request_authentication()
  File "env/lib/python3.11/site-packages/pymysql/connections.py", line 911, in _request_authentication
    auth_packet = self._read_packet()
                  ^^^^^^^^^^^^^^^^^^^
  File "env/lib/python3.11/site-packages/pymysql/connections.py", line 729, in _read_packet
    packet.raise_for_error()
  File "env/lib/python3.11/site-packages/pymysql/protocol.py", line 221, in raise_for_error
    err.raise_mysql_exception(self._data)
  File "env/lib/python3.11/site-packages/pymysql/err.py", line 143, in raise_mysql_exception
    raise errorclass(errno, errval)
pymysql.err.OperationalError: (1049, "Unknown database '_3f14d08a0477f193'")

2023-11-14 11:05:44,155 ERROR scheduler Exception in Enqueue Events for Site srdc.local
Traceback (most recent call last):
  File "apps/frappe/frappe/utils/scheduler.py", line 75, in enqueue_events_for_site
    if is_scheduler_inactive():
       ^^^^^^^^^^^^^^^^^^^^^^^
  File "apps/frappe/frappe/utils/scheduler.py", line 114, in is_scheduler_inactive
    if is_scheduler_disabled(verbose=verbose):
       ^^^^^^^^^^^^^^^^^^^^^^^^^^^^^^^^^^^^^^
  File "apps/frappe/frappe/utils/scheduler.py", line 127, in is_scheduler_disabled
    frappe.db.get_single_value("System Settings", "enable_scheduler")
  File "apps/frappe/frappe/database/database.py", line 786, in get_single_value
    ).run()
      ^^^^^
  File "apps/frappe/frappe/query_builder/utils.py", line 87, in execute_query
    result = frappe.db.sql(query, params, *args, **kwargs)  # nosemgrep
             ^^^^^^^^^^^^^^^^^^^^^^^^^^^^^^^^^^^^^^^^^^^^^
  File "apps/frappe/frappe/database/database.py", line 201, in sql
    self.connect()
  File "apps/frappe/frappe/database/database.py", line 115, in connect
    self._conn = self.get_connection()
                 ^^^^^^^^^^^^^^^^^^^^^
  File "apps/frappe/frappe/database/mariadb/database.py", line 98, in get_connection
    conn = self._get_connection()
           ^^^^^^^^^^^^^^^^^^^^^^
  File "apps/frappe/frappe/database/mariadb/database.py", line 104, in _get_connection
    return self.create_connection()
           ^^^^^^^^^^^^^^^^^^^^^^^^
  File "apps/frappe/frappe/database/mariadb/database.py", line 107, in create_connection
    return pymysql.connect(**self.get_connection_settings())
           ^^^^^^^^^^^^^^^^^^^^^^^^^^^^^^^^^^^^^^^^^^^^^^^^^
  File "env/lib/python3.11/site-packages/pymysql/connections.py", line 352, in __init__
    self.connect()
  File "env/lib/python3.11/site-packages/pymysql/connections.py", line 636, in connect
    self._request_authentication()
  File "env/lib/python3.11/site-packages/pymysql/connections.py", line 911, in _request_authentication
    auth_packet = self._read_packet()
                  ^^^^^^^^^^^^^^^^^^^
  File "env/lib/python3.11/site-packages/pymysql/connections.py", line 729, in _read_packet
    packet.raise_for_error()
  File "env/lib/python3.11/site-packages/pymysql/protocol.py", line 221, in raise_for_error
    err.raise_mysql_exception(self._data)
  File "env/lib/python3.11/site-packages/pymysql/err.py", line 143, in raise_mysql_exception
    raise errorclass(errno, errval)
pymysql.err.OperationalError: (1049, "Unknown database '_3f14d08a0477f193'")

2023-11-14 11:05:44,156 ERROR scheduler Exception in Enqueue Events for Site erp.srdc.io
Traceback (most recent call last):
  File "apps/frappe/frappe/utils/scheduler.py", line 75, in enqueue_events_for_site
    if is_scheduler_inactive():
       ^^^^^^^^^^^^^^^^^^^^^^^
  File "apps/frappe/frappe/utils/scheduler.py", line 114, in is_scheduler_inactive
    if is_scheduler_disabled(verbose=verbose):
       ^^^^^^^^^^^^^^^^^^^^^^^^^^^^^^^^^^^^^^
  File "apps/frappe/frappe/utils/scheduler.py", line 127, in is_scheduler_disabled
    frappe.db.get_single_value("System Settings", "enable_scheduler")
  File "apps/frappe/frappe/database/database.py", line 786, in get_single_value
    ).run()
      ^^^^^
  File "apps/frappe/frappe/query_builder/utils.py", line 87, in execute_query
    result = frappe.db.sql(query, params, *args, **kwargs)  # nosemgrep
             ^^^^^^^^^^^^^^^^^^^^^^^^^^^^^^^^^^^^^^^^^^^^^
  File "apps/frappe/frappe/database/database.py", line 201, in sql
    self.connect()
  File "apps/frappe/frappe/database/database.py", line 115, in connect
    self._conn = self.get_connection()
                 ^^^^^^^^^^^^^^^^^^^^^
  File "apps/frappe/frappe/database/mariadb/database.py", line 98, in get_connection
    conn = self._get_connection()
           ^^^^^^^^^^^^^^^^^^^^^^
  File "apps/frappe/frappe/database/mariadb/database.py", line 104, in _get_connection
    return self.create_connection()
           ^^^^^^^^^^^^^^^^^^^^^^^^
  File "apps/frappe/frappe/database/mariadb/database.py", line 107, in create_connection
    return pymysql.connect(**self.get_connection_settings())
           ^^^^^^^^^^^^^^^^^^^^^^^^^^^^^^^^^^^^^^^^^^^^^^^^^
  File "env/lib/python3.11/site-packages/pymysql/connections.py", line 352, in __init__
    self.connect()
  File "env/lib/python3.11/site-packages/pymysql/connections.py", line 636, in connect
    self._request_authentication()
  File "env/lib/python3.11/site-packages/pymysql/connections.py", line 911, in _request_authentication
    auth_packet = self._read_packet()
                  ^^^^^^^^^^^^^^^^^^^
  File "env/lib/python3.11/site-packages/pymysql/connections.py", line 729, in _read_packet
    packet.raise_for_error()
  File "env/lib/python3.11/site-packages/pymysql/protocol.py", line 221, in raise_for_error
    err.raise_mysql_exception(self._data)
  File "env/lib/python3.11/site-packages/pymysql/err.py", line 143, in raise_mysql_exception
    raise errorclass(errno, errval)
pymysql.err.OperationalError: (1049, "Unknown database '_9b8e683170b398ec'")

2023-11-14 11:06:44,161 ERROR scheduler Exception in Enqueue Events for Site srdc.local
Traceback (most recent call last):
  File "apps/frappe/frappe/utils/scheduler.py", line 75, in enqueue_events_for_site
    if is_scheduler_inactive():
       ^^^^^^^^^^^^^^^^^^^^^^^
  File "apps/frappe/frappe/utils/scheduler.py", line 114, in is_scheduler_inactive
    if is_scheduler_disabled(verbose=verbose):
       ^^^^^^^^^^^^^^^^^^^^^^^^^^^^^^^^^^^^^^
  File "apps/frappe/frappe/utils/scheduler.py", line 127, in is_scheduler_disabled
    frappe.db.get_single_value("System Settings", "enable_scheduler")
  File "apps/frappe/frappe/database/database.py", line 786, in get_single_value
    ).run()
      ^^^^^
  File "apps/frappe/frappe/query_builder/utils.py", line 87, in execute_query
    result = frappe.db.sql(query, params, *args, **kwargs)  # nosemgrep
             ^^^^^^^^^^^^^^^^^^^^^^^^^^^^^^^^^^^^^^^^^^^^^
  File "apps/frappe/frappe/database/database.py", line 201, in sql
    self.connect()
  File "apps/frappe/frappe/database/database.py", line 115, in connect
    self._conn = self.get_connection()
                 ^^^^^^^^^^^^^^^^^^^^^
  File "apps/frappe/frappe/database/mariadb/database.py", line 98, in get_connection
    conn = self._get_connection()
           ^^^^^^^^^^^^^^^^^^^^^^
  File "apps/frappe/frappe/database/mariadb/database.py", line 104, in _get_connection
    return self.create_connection()
           ^^^^^^^^^^^^^^^^^^^^^^^^
  File "apps/frappe/frappe/database/mariadb/database.py", line 107, in create_connection
    return pymysql.connect(**self.get_connection_settings())
           ^^^^^^^^^^^^^^^^^^^^^^^^^^^^^^^^^^^^^^^^^^^^^^^^^
  File "env/lib/python3.11/site-packages/pymysql/connections.py", line 352, in __init__
    self.connect()
  File "env/lib/python3.11/site-packages/pymysql/connections.py", line 636, in connect
    self._request_authentication()
  File "env/lib/python3.11/site-packages/pymysql/connections.py", line 911, in _request_authentication
    auth_packet = self._read_packet()
                  ^^^^^^^^^^^^^^^^^^^
  File "env/lib/python3.11/site-packages/pymysql/connections.py", line 729, in _read_packet
    packet.raise_for_error()
  File "env/lib/python3.11/site-packages/pymysql/protocol.py", line 221, in raise_for_error
    err.raise_mysql_exception(self._data)
  File "env/lib/python3.11/site-packages/pymysql/err.py", line 143, in raise_mysql_exception
    raise errorclass(errno, errval)
pymysql.err.OperationalError: (1049, "Unknown database '_3f14d08a0477f193'")

2023-11-14 11:06:44,173 ERROR scheduler Exception in Enqueue Events for Site erp.srdc.io
Traceback (most recent call last):
  File "apps/frappe/frappe/utils/scheduler.py", line 75, in enqueue_events_for_site
    if is_scheduler_inactive():
       ^^^^^^^^^^^^^^^^^^^^^^^
  File "apps/frappe/frappe/utils/scheduler.py", line 114, in is_scheduler_inactive
    if is_scheduler_disabled(verbose=verbose):
       ^^^^^^^^^^^^^^^^^^^^^^^^^^^^^^^^^^^^^^
  File "apps/frappe/frappe/utils/scheduler.py", line 127, in is_scheduler_disabled
    frappe.db.get_single_value("System Settings", "enable_scheduler")
  File "apps/frappe/frappe/database/database.py", line 786, in get_single_value
    ).run()
      ^^^^^
  File "apps/frappe/frappe/query_builder/utils.py", line 87, in execute_query
    result = frappe.db.sql(query, params, *args, **kwargs)  # nosemgrep
             ^^^^^^^^^^^^^^^^^^^^^^^^^^^^^^^^^^^^^^^^^^^^^
  File "apps/frappe/frappe/database/database.py", line 201, in sql
    self.connect()
  File "apps/frappe/frappe/database/database.py", line 115, in connect
    self._conn = self.get_connection()
                 ^^^^^^^^^^^^^^^^^^^^^
  File "apps/frappe/frappe/database/mariadb/database.py", line 98, in get_connection
    conn = self._get_connection()
           ^^^^^^^^^^^^^^^^^^^^^^
  File "apps/frappe/frappe/database/mariadb/database.py", line 104, in _get_connection
    return self.create_connection()
           ^^^^^^^^^^^^^^^^^^^^^^^^
  File "apps/frappe/frappe/database/mariadb/database.py", line 107, in create_connection
    return pymysql.connect(**self.get_connection_settings())
           ^^^^^^^^^^^^^^^^^^^^^^^^^^^^^^^^^^^^^^^^^^^^^^^^^
  File "env/lib/python3.11/site-packages/pymysql/connections.py", line 352, in __init__
    self.connect()
  File "env/lib/python3.11/site-packages/pymysql/connections.py", line 636, in connect
    self._request_authentication()
  File "env/lib/python3.11/site-packages/pymysql/connections.py", line 911, in _request_authentication
    auth_packet = self._read_packet()
                  ^^^^^^^^^^^^^^^^^^^
  File "env/lib/python3.11/site-packages/pymysql/connections.py", line 729, in _read_packet
    packet.raise_for_error()
  File "env/lib/python3.11/site-packages/pymysql/protocol.py", line 221, in raise_for_error
    err.raise_mysql_exception(self._data)
  File "env/lib/python3.11/site-packages/pymysql/err.py", line 143, in raise_mysql_exception
    raise errorclass(errno, errval)
pymysql.err.OperationalError: (1049, "Unknown database '_9b8e683170b398ec'")

2023-11-14 11:07:44,191 ERROR scheduler Exception in Enqueue Events for Site erp.srdc.io
Traceback (most recent call last):
  File "apps/frappe/frappe/utils/scheduler.py", line 75, in enqueue_events_for_site
    if is_scheduler_inactive():
       ^^^^^^^^^^^^^^^^^^^^^^^
  File "apps/frappe/frappe/utils/scheduler.py", line 114, in is_scheduler_inactive
    if is_scheduler_disabled(verbose=verbose):
       ^^^^^^^^^^^^^^^^^^^^^^^^^^^^^^^^^^^^^^
  File "apps/frappe/frappe/utils/scheduler.py", line 127, in is_scheduler_disabled
    frappe.db.get_single_value("System Settings", "enable_scheduler")
  File "apps/frappe/frappe/database/database.py", line 786, in get_single_value
    ).run()
      ^^^^^
  File "apps/frappe/frappe/query_builder/utils.py", line 87, in execute_query
    result = frappe.db.sql(query, params, *args, **kwargs)  # nosemgrep
             ^^^^^^^^^^^^^^^^^^^^^^^^^^^^^^^^^^^^^^^^^^^^^
  File "apps/frappe/frappe/database/database.py", line 201, in sql
    self.connect()
  File "apps/frappe/frappe/database/database.py", line 115, in connect
    self._conn = self.get_connection()
                 ^^^^^^^^^^^^^^^^^^^^^
  File "apps/frappe/frappe/database/mariadb/database.py", line 98, in get_connection
    conn = self._get_connection()
           ^^^^^^^^^^^^^^^^^^^^^^
  File "apps/frappe/frappe/database/mariadb/database.py", line 104, in _get_connection
    return self.create_connection()
           ^^^^^^^^^^^^^^^^^^^^^^^^
  File "apps/frappe/frappe/database/mariadb/database.py", line 107, in create_connection
    return pymysql.connect(**self.get_connection_settings())
           ^^^^^^^^^^^^^^^^^^^^^^^^^^^^^^^^^^^^^^^^^^^^^^^^^
  File "env/lib/python3.11/site-packages/pymysql/connections.py", line 352, in __init__
    self.connect()
  File "env/lib/python3.11/site-packages/pymysql/connections.py", line 636, in connect
    self._request_authentication()
  File "env/lib/python3.11/site-packages/pymysql/connections.py", line 911, in _request_authentication
    auth_packet = self._read_packet()
                  ^^^^^^^^^^^^^^^^^^^
  File "env/lib/python3.11/site-packages/pymysql/connections.py", line 729, in _read_packet
    packet.raise_for_error()
  File "env/lib/python3.11/site-packages/pymysql/protocol.py", line 221, in raise_for_error
    err.raise_mysql_exception(self._data)
  File "env/lib/python3.11/site-packages/pymysql/err.py", line 143, in raise_mysql_exception
    raise errorclass(errno, errval)
pymysql.err.OperationalError: (1049, "Unknown database '_9b8e683170b398ec'")

2023-11-14 11:07:44,200 ERROR scheduler Exception in Enqueue Events for Site srdc.local
Traceback (most recent call last):
  File "apps/frappe/frappe/utils/scheduler.py", line 75, in enqueue_events_for_site
    if is_scheduler_inactive():
       ^^^^^^^^^^^^^^^^^^^^^^^
  File "apps/frappe/frappe/utils/scheduler.py", line 114, in is_scheduler_inactive
    if is_scheduler_disabled(verbose=verbose):
       ^^^^^^^^^^^^^^^^^^^^^^^^^^^^^^^^^^^^^^
  File "apps/frappe/frappe/utils/scheduler.py", line 127, in is_scheduler_disabled
    frappe.db.get_single_value("System Settings", "enable_scheduler")
  File "apps/frappe/frappe/database/database.py", line 786, in get_single_value
    ).run()
      ^^^^^
  File "apps/frappe/frappe/query_builder/utils.py", line 87, in execute_query
    result = frappe.db.sql(query, params, *args, **kwargs)  # nosemgrep
             ^^^^^^^^^^^^^^^^^^^^^^^^^^^^^^^^^^^^^^^^^^^^^
  File "apps/frappe/frappe/database/database.py", line 201, in sql
    self.connect()
  File "apps/frappe/frappe/database/database.py", line 115, in connect
    self._conn = self.get_connection()
                 ^^^^^^^^^^^^^^^^^^^^^
  File "apps/frappe/frappe/database/mariadb/database.py", line 98, in get_connection
    conn = self._get_connection()
           ^^^^^^^^^^^^^^^^^^^^^^
  File "apps/frappe/frappe/database/mariadb/database.py", line 104, in _get_connection
    return self.create_connection()
           ^^^^^^^^^^^^^^^^^^^^^^^^
  File "apps/frappe/frappe/database/mariadb/database.py", line 107, in create_connection
    return pymysql.connect(**self.get_connection_settings())
           ^^^^^^^^^^^^^^^^^^^^^^^^^^^^^^^^^^^^^^^^^^^^^^^^^
  File "env/lib/python3.11/site-packages/pymysql/connections.py", line 352, in __init__
    self.connect()
  File "env/lib/python3.11/site-packages/pymysql/connections.py", line 636, in connect
    self._request_authentication()
  File "env/lib/python3.11/site-packages/pymysql/connections.py", line 911, in _request_authentication
    auth_packet = self._read_packet()
                  ^^^^^^^^^^^^^^^^^^^
  File "env/lib/python3.11/site-packages/pymysql/connections.py", line 729, in _read_packet
    packet.raise_for_error()
  File "env/lib/python3.11/site-packages/pymysql/protocol.py", line 221, in raise_for_error
    err.raise_mysql_exception(self._data)
  File "env/lib/python3.11/site-packages/pymysql/err.py", line 143, in raise_mysql_exception
    raise errorclass(errno, errval)
pymysql.err.OperationalError: (1049, "Unknown database '_3f14d08a0477f193'")

2023-11-14 11:10:40,753 ERROR scheduler Exception in Enqueue Events for Site erp.srdc.io
Traceback (most recent call last):
  File "apps/frappe/frappe/utils/scheduler.py", line 75, in enqueue_events_for_site
    if is_scheduler_inactive():
       ^^^^^^^^^^^^^^^^^^^^^^^
  File "apps/frappe/frappe/utils/scheduler.py", line 114, in is_scheduler_inactive
    if is_scheduler_disabled(verbose=verbose):
       ^^^^^^^^^^^^^^^^^^^^^^^^^^^^^^^^^^^^^^
  File "apps/frappe/frappe/utils/scheduler.py", line 127, in is_scheduler_disabled
    frappe.db.get_single_value("System Settings", "enable_scheduler")
  File "apps/frappe/frappe/database/database.py", line 786, in get_single_value
    ).run()
      ^^^^^
  File "apps/frappe/frappe/query_builder/utils.py", line 87, in execute_query
    result = frappe.db.sql(query, params, *args, **kwargs)  # nosemgrep
             ^^^^^^^^^^^^^^^^^^^^^^^^^^^^^^^^^^^^^^^^^^^^^
  File "apps/frappe/frappe/database/database.py", line 201, in sql
    self.connect()
  File "apps/frappe/frappe/database/database.py", line 115, in connect
    self._conn = self.get_connection()
                 ^^^^^^^^^^^^^^^^^^^^^
  File "apps/frappe/frappe/database/mariadb/database.py", line 98, in get_connection
    conn = self._get_connection()
           ^^^^^^^^^^^^^^^^^^^^^^
  File "apps/frappe/frappe/database/mariadb/database.py", line 104, in _get_connection
    return self.create_connection()
           ^^^^^^^^^^^^^^^^^^^^^^^^
  File "apps/frappe/frappe/database/mariadb/database.py", line 107, in create_connection
    return pymysql.connect(**self.get_connection_settings())
           ^^^^^^^^^^^^^^^^^^^^^^^^^^^^^^^^^^^^^^^^^^^^^^^^^
  File "env/lib/python3.11/site-packages/pymysql/connections.py", line 352, in __init__
    self.connect()
  File "env/lib/python3.11/site-packages/pymysql/connections.py", line 636, in connect
    self._request_authentication()
  File "env/lib/python3.11/site-packages/pymysql/connections.py", line 911, in _request_authentication
    auth_packet = self._read_packet()
                  ^^^^^^^^^^^^^^^^^^^
  File "env/lib/python3.11/site-packages/pymysql/connections.py", line 729, in _read_packet
    packet.raise_for_error()
  File "env/lib/python3.11/site-packages/pymysql/protocol.py", line 221, in raise_for_error
    err.raise_mysql_exception(self._data)
  File "env/lib/python3.11/site-packages/pymysql/err.py", line 143, in raise_mysql_exception
    raise errorclass(errno, errval)
pymysql.err.OperationalError: (1049, "Unknown database '_9b8e683170b398ec'")

2023-11-14 11:10:40,755 ERROR scheduler Exception in Enqueue Events for Site srdc.local
Traceback (most recent call last):
  File "apps/frappe/frappe/utils/scheduler.py", line 75, in enqueue_events_for_site
    if is_scheduler_inactive():
       ^^^^^^^^^^^^^^^^^^^^^^^
  File "apps/frappe/frappe/utils/scheduler.py", line 114, in is_scheduler_inactive
    if is_scheduler_disabled(verbose=verbose):
       ^^^^^^^^^^^^^^^^^^^^^^^^^^^^^^^^^^^^^^
  File "apps/frappe/frappe/utils/scheduler.py", line 127, in is_scheduler_disabled
    frappe.db.get_single_value("System Settings", "enable_scheduler")
  File "apps/frappe/frappe/database/database.py", line 786, in get_single_value
    ).run()
      ^^^^^
  File "apps/frappe/frappe/query_builder/utils.py", line 87, in execute_query
    result = frappe.db.sql(query, params, *args, **kwargs)  # nosemgrep
             ^^^^^^^^^^^^^^^^^^^^^^^^^^^^^^^^^^^^^^^^^^^^^
  File "apps/frappe/frappe/database/database.py", line 201, in sql
    self.connect()
  File "apps/frappe/frappe/database/database.py", line 115, in connect
    self._conn = self.get_connection()
                 ^^^^^^^^^^^^^^^^^^^^^
  File "apps/frappe/frappe/database/mariadb/database.py", line 98, in get_connection
    conn = self._get_connection()
           ^^^^^^^^^^^^^^^^^^^^^^
  File "apps/frappe/frappe/database/mariadb/database.py", line 104, in _get_connection
    return self.create_connection()
           ^^^^^^^^^^^^^^^^^^^^^^^^
  File "apps/frappe/frappe/database/mariadb/database.py", line 107, in create_connection
    return pymysql.connect(**self.get_connection_settings())
           ^^^^^^^^^^^^^^^^^^^^^^^^^^^^^^^^^^^^^^^^^^^^^^^^^
  File "env/lib/python3.11/site-packages/pymysql/connections.py", line 352, in __init__
    self.connect()
  File "env/lib/python3.11/site-packages/pymysql/connections.py", line 636, in connect
    self._request_authentication()
  File "env/lib/python3.11/site-packages/pymysql/connections.py", line 911, in _request_authentication
    auth_packet = self._read_packet()
                  ^^^^^^^^^^^^^^^^^^^
  File "env/lib/python3.11/site-packages/pymysql/connections.py", line 729, in _read_packet
    packet.raise_for_error()
  File "env/lib/python3.11/site-packages/pymysql/protocol.py", line 221, in raise_for_error
    err.raise_mysql_exception(self._data)
  File "env/lib/python3.11/site-packages/pymysql/err.py", line 143, in raise_mysql_exception
    raise errorclass(errno, errval)
pymysql.err.OperationalError: (1049, "Unknown database '_3f14d08a0477f193'")

2023-11-14 11:11:40,762 ERROR scheduler Exception in Enqueue Events for Site erp.srdc.io
Traceback (most recent call last):
  File "apps/frappe/frappe/utils/scheduler.py", line 75, in enqueue_events_for_site
    if is_scheduler_inactive():
       ^^^^^^^^^^^^^^^^^^^^^^^
  File "apps/frappe/frappe/utils/scheduler.py", line 114, in is_scheduler_inactive
    if is_scheduler_disabled(verbose=verbose):
       ^^^^^^^^^^^^^^^^^^^^^^^^^^^^^^^^^^^^^^
  File "apps/frappe/frappe/utils/scheduler.py", line 127, in is_scheduler_disabled
    frappe.db.get_single_value("System Settings", "enable_scheduler")
  File "apps/frappe/frappe/database/database.py", line 786, in get_single_value
    ).run()
      ^^^^^
  File "apps/frappe/frappe/query_builder/utils.py", line 87, in execute_query
    result = frappe.db.sql(query, params, *args, **kwargs)  # nosemgrep
             ^^^^^^^^^^^^^^^^^^^^^^^^^^^^^^^^^^^^^^^^^^^^^
  File "apps/frappe/frappe/database/database.py", line 201, in sql
    self.connect()
  File "apps/frappe/frappe/database/database.py", line 115, in connect
    self._conn = self.get_connection()
                 ^^^^^^^^^^^^^^^^^^^^^
  File "apps/frappe/frappe/database/mariadb/database.py", line 98, in get_connection
    conn = self._get_connection()
           ^^^^^^^^^^^^^^^^^^^^^^
  File "apps/frappe/frappe/database/mariadb/database.py", line 104, in _get_connection
    return self.create_connection()
           ^^^^^^^^^^^^^^^^^^^^^^^^
  File "apps/frappe/frappe/database/mariadb/database.py", line 107, in create_connection
    return pymysql.connect(**self.get_connection_settings())
           ^^^^^^^^^^^^^^^^^^^^^^^^^^^^^^^^^^^^^^^^^^^^^^^^^
  File "env/lib/python3.11/site-packages/pymysql/connections.py", line 352, in __init__
    self.connect()
  File "env/lib/python3.11/site-packages/pymysql/connections.py", line 636, in connect
    self._request_authentication()
  File "env/lib/python3.11/site-packages/pymysql/connections.py", line 911, in _request_authentication
    auth_packet = self._read_packet()
                  ^^^^^^^^^^^^^^^^^^^
  File "env/lib/python3.11/site-packages/pymysql/connections.py", line 729, in _read_packet
    packet.raise_for_error()
  File "env/lib/python3.11/site-packages/pymysql/protocol.py", line 221, in raise_for_error
    err.raise_mysql_exception(self._data)
  File "env/lib/python3.11/site-packages/pymysql/err.py", line 143, in raise_mysql_exception
    raise errorclass(errno, errval)
pymysql.err.OperationalError: (1049, "Unknown database '_9b8e683170b398ec'")

2023-11-14 11:11:40,765 ERROR scheduler Exception in Enqueue Events for Site srdc.local
Traceback (most recent call last):
  File "apps/frappe/frappe/utils/scheduler.py", line 75, in enqueue_events_for_site
    if is_scheduler_inactive():
       ^^^^^^^^^^^^^^^^^^^^^^^
  File "apps/frappe/frappe/utils/scheduler.py", line 114, in is_scheduler_inactive
    if is_scheduler_disabled(verbose=verbose):
       ^^^^^^^^^^^^^^^^^^^^^^^^^^^^^^^^^^^^^^
  File "apps/frappe/frappe/utils/scheduler.py", line 127, in is_scheduler_disabled
    frappe.db.get_single_value("System Settings", "enable_scheduler")
  File "apps/frappe/frappe/database/database.py", line 786, in get_single_value
    ).run()
      ^^^^^
  File "apps/frappe/frappe/query_builder/utils.py", line 87, in execute_query
    result = frappe.db.sql(query, params, *args, **kwargs)  # nosemgrep
             ^^^^^^^^^^^^^^^^^^^^^^^^^^^^^^^^^^^^^^^^^^^^^
  File "apps/frappe/frappe/database/database.py", line 201, in sql
    self.connect()
  File "apps/frappe/frappe/database/database.py", line 115, in connect
    self._conn = self.get_connection()
                 ^^^^^^^^^^^^^^^^^^^^^
  File "apps/frappe/frappe/database/mariadb/database.py", line 98, in get_connection
    conn = self._get_connection()
           ^^^^^^^^^^^^^^^^^^^^^^
  File "apps/frappe/frappe/database/mariadb/database.py", line 104, in _get_connection
    return self.create_connection()
           ^^^^^^^^^^^^^^^^^^^^^^^^
  File "apps/frappe/frappe/database/mariadb/database.py", line 107, in create_connection
    return pymysql.connect(**self.get_connection_settings())
           ^^^^^^^^^^^^^^^^^^^^^^^^^^^^^^^^^^^^^^^^^^^^^^^^^
  File "env/lib/python3.11/site-packages/pymysql/connections.py", line 352, in __init__
    self.connect()
  File "env/lib/python3.11/site-packages/pymysql/connections.py", line 636, in connect
    self._request_authentication()
  File "env/lib/python3.11/site-packages/pymysql/connections.py", line 911, in _request_authentication
    auth_packet = self._read_packet()
                  ^^^^^^^^^^^^^^^^^^^
  File "env/lib/python3.11/site-packages/pymysql/connections.py", line 729, in _read_packet
    packet.raise_for_error()
  File "env/lib/python3.11/site-packages/pymysql/protocol.py", line 221, in raise_for_error
    err.raise_mysql_exception(self._data)
  File "env/lib/python3.11/site-packages/pymysql/err.py", line 143, in raise_mysql_exception
    raise errorclass(errno, errval)
pymysql.err.OperationalError: (1049, "Unknown database '_3f14d08a0477f193'")

2023-11-14 11:13:18,361 ERROR scheduler Exception in Enqueue Events for Site erp.srdc.io
Traceback (most recent call last):
  File "apps/frappe/frappe/utils/scheduler.py", line 75, in enqueue_events_for_site
    if is_scheduler_inactive():
       ^^^^^^^^^^^^^^^^^^^^^^^
  File "apps/frappe/frappe/utils/scheduler.py", line 114, in is_scheduler_inactive
    if is_scheduler_disabled(verbose=verbose):
       ^^^^^^^^^^^^^^^^^^^^^^^^^^^^^^^^^^^^^^
  File "apps/frappe/frappe/utils/scheduler.py", line 127, in is_scheduler_disabled
    frappe.db.get_single_value("System Settings", "enable_scheduler")
  File "apps/frappe/frappe/database/database.py", line 786, in get_single_value
    ).run()
      ^^^^^
  File "apps/frappe/frappe/query_builder/utils.py", line 87, in execute_query
    result = frappe.db.sql(query, params, *args, **kwargs)  # nosemgrep
             ^^^^^^^^^^^^^^^^^^^^^^^^^^^^^^^^^^^^^^^^^^^^^
  File "apps/frappe/frappe/database/database.py", line 201, in sql
    self.connect()
  File "apps/frappe/frappe/database/database.py", line 115, in connect
    self._conn = self.get_connection()
                 ^^^^^^^^^^^^^^^^^^^^^
  File "apps/frappe/frappe/database/mariadb/database.py", line 98, in get_connection
    conn = self._get_connection()
           ^^^^^^^^^^^^^^^^^^^^^^
  File "apps/frappe/frappe/database/mariadb/database.py", line 104, in _get_connection
    return self.create_connection()
           ^^^^^^^^^^^^^^^^^^^^^^^^
  File "apps/frappe/frappe/database/mariadb/database.py", line 107, in create_connection
    return pymysql.connect(**self.get_connection_settings())
           ^^^^^^^^^^^^^^^^^^^^^^^^^^^^^^^^^^^^^^^^^^^^^^^^^
  File "env/lib/python3.11/site-packages/pymysql/connections.py", line 352, in __init__
    self.connect()
  File "env/lib/python3.11/site-packages/pymysql/connections.py", line 636, in connect
    self._request_authentication()
  File "env/lib/python3.11/site-packages/pymysql/connections.py", line 911, in _request_authentication
    auth_packet = self._read_packet()
                  ^^^^^^^^^^^^^^^^^^^
  File "env/lib/python3.11/site-packages/pymysql/connections.py", line 729, in _read_packet
    packet.raise_for_error()
  File "env/lib/python3.11/site-packages/pymysql/protocol.py", line 221, in raise_for_error
    err.raise_mysql_exception(self._data)
  File "env/lib/python3.11/site-packages/pymysql/err.py", line 143, in raise_mysql_exception
    raise errorclass(errno, errval)
pymysql.err.OperationalError: (1049, "Unknown database '_9b8e683170b398ec'")

2023-11-14 11:13:18,364 ERROR scheduler Exception in Enqueue Events for Site srdc.local
Traceback (most recent call last):
  File "apps/frappe/frappe/utils/scheduler.py", line 75, in enqueue_events_for_site
    if is_scheduler_inactive():
       ^^^^^^^^^^^^^^^^^^^^^^^
  File "apps/frappe/frappe/utils/scheduler.py", line 114, in is_scheduler_inactive
    if is_scheduler_disabled(verbose=verbose):
       ^^^^^^^^^^^^^^^^^^^^^^^^^^^^^^^^^^^^^^
  File "apps/frappe/frappe/utils/scheduler.py", line 127, in is_scheduler_disabled
    frappe.db.get_single_value("System Settings", "enable_scheduler")
  File "apps/frappe/frappe/database/database.py", line 786, in get_single_value
    ).run()
      ^^^^^
  File "apps/frappe/frappe/query_builder/utils.py", line 87, in execute_query
    result = frappe.db.sql(query, params, *args, **kwargs)  # nosemgrep
             ^^^^^^^^^^^^^^^^^^^^^^^^^^^^^^^^^^^^^^^^^^^^^
  File "apps/frappe/frappe/database/database.py", line 201, in sql
    self.connect()
  File "apps/frappe/frappe/database/database.py", line 115, in connect
    self._conn = self.get_connection()
                 ^^^^^^^^^^^^^^^^^^^^^
  File "apps/frappe/frappe/database/mariadb/database.py", line 98, in get_connection
    conn = self._get_connection()
           ^^^^^^^^^^^^^^^^^^^^^^
  File "apps/frappe/frappe/database/mariadb/database.py", line 104, in _get_connection
    return self.create_connection()
           ^^^^^^^^^^^^^^^^^^^^^^^^
  File "apps/frappe/frappe/database/mariadb/database.py", line 107, in create_connection
    return pymysql.connect(**self.get_connection_settings())
           ^^^^^^^^^^^^^^^^^^^^^^^^^^^^^^^^^^^^^^^^^^^^^^^^^
  File "env/lib/python3.11/site-packages/pymysql/connections.py", line 352, in __init__
    self.connect()
  File "env/lib/python3.11/site-packages/pymysql/connections.py", line 636, in connect
    self._request_authentication()
  File "env/lib/python3.11/site-packages/pymysql/connections.py", line 911, in _request_authentication
    auth_packet = self._read_packet()
                  ^^^^^^^^^^^^^^^^^^^
  File "env/lib/python3.11/site-packages/pymysql/connections.py", line 729, in _read_packet
    packet.raise_for_error()
  File "env/lib/python3.11/site-packages/pymysql/protocol.py", line 221, in raise_for_error
    err.raise_mysql_exception(self._data)
  File "env/lib/python3.11/site-packages/pymysql/err.py", line 143, in raise_mysql_exception
    raise errorclass(errno, errval)
pymysql.err.OperationalError: (1049, "Unknown database '_3f14d08a0477f193'")

2023-11-14 11:14:18,382 ERROR scheduler Exception in Enqueue Events for Site srdc.local
Traceback (most recent call last):
  File "apps/frappe/frappe/utils/scheduler.py", line 75, in enqueue_events_for_site
    if is_scheduler_inactive():
       ^^^^^^^^^^^^^^^^^^^^^^^
  File "apps/frappe/frappe/utils/scheduler.py", line 114, in is_scheduler_inactive
    if is_scheduler_disabled(verbose=verbose):
       ^^^^^^^^^^^^^^^^^^^^^^^^^^^^^^^^^^^^^^
  File "apps/frappe/frappe/utils/scheduler.py", line 127, in is_scheduler_disabled
    frappe.db.get_single_value("System Settings", "enable_scheduler")
  File "apps/frappe/frappe/database/database.py", line 786, in get_single_value
    ).run()
      ^^^^^
  File "apps/frappe/frappe/query_builder/utils.py", line 87, in execute_query
    result = frappe.db.sql(query, params, *args, **kwargs)  # nosemgrep
             ^^^^^^^^^^^^^^^^^^^^^^^^^^^^^^^^^^^^^^^^^^^^^
  File "apps/frappe/frappe/database/database.py", line 201, in sql
    self.connect()
  File "apps/frappe/frappe/database/database.py", line 115, in connect
    self._conn = self.get_connection()
                 ^^^^^^^^^^^^^^^^^^^^^
  File "apps/frappe/frappe/database/mariadb/database.py", line 98, in get_connection
    conn = self._get_connection()
           ^^^^^^^^^^^^^^^^^^^^^^
  File "apps/frappe/frappe/database/mariadb/database.py", line 104, in _get_connection
    return self.create_connection()
           ^^^^^^^^^^^^^^^^^^^^^^^^
  File "apps/frappe/frappe/database/mariadb/database.py", line 107, in create_connection
    return pymysql.connect(**self.get_connection_settings())
           ^^^^^^^^^^^^^^^^^^^^^^^^^^^^^^^^^^^^^^^^^^^^^^^^^
  File "env/lib/python3.11/site-packages/pymysql/connections.py", line 352, in __init__
    self.connect()
  File "env/lib/python3.11/site-packages/pymysql/connections.py", line 636, in connect
    self._request_authentication()
  File "env/lib/python3.11/site-packages/pymysql/connections.py", line 911, in _request_authentication
    auth_packet = self._read_packet()
                  ^^^^^^^^^^^^^^^^^^^
  File "env/lib/python3.11/site-packages/pymysql/connections.py", line 729, in _read_packet
    packet.raise_for_error()
  File "env/lib/python3.11/site-packages/pymysql/protocol.py", line 221, in raise_for_error
    err.raise_mysql_exception(self._data)
  File "env/lib/python3.11/site-packages/pymysql/err.py", line 143, in raise_mysql_exception
    raise errorclass(errno, errval)
pymysql.err.OperationalError: (1049, "Unknown database '_3f14d08a0477f193'")

2023-11-14 11:14:18,390 ERROR scheduler Exception in Enqueue Events for Site erp.srdc.io
Traceback (most recent call last):
  File "apps/frappe/frappe/utils/scheduler.py", line 75, in enqueue_events_for_site
    if is_scheduler_inactive():
       ^^^^^^^^^^^^^^^^^^^^^^^
  File "apps/frappe/frappe/utils/scheduler.py", line 114, in is_scheduler_inactive
    if is_scheduler_disabled(verbose=verbose):
       ^^^^^^^^^^^^^^^^^^^^^^^^^^^^^^^^^^^^^^
  File "apps/frappe/frappe/utils/scheduler.py", line 127, in is_scheduler_disabled
    frappe.db.get_single_value("System Settings", "enable_scheduler")
  File "apps/frappe/frappe/database/database.py", line 786, in get_single_value
    ).run()
      ^^^^^
  File "apps/frappe/frappe/query_builder/utils.py", line 87, in execute_query
    result = frappe.db.sql(query, params, *args, **kwargs)  # nosemgrep
             ^^^^^^^^^^^^^^^^^^^^^^^^^^^^^^^^^^^^^^^^^^^^^
  File "apps/frappe/frappe/database/database.py", line 201, in sql
    self.connect()
  File "apps/frappe/frappe/database/database.py", line 115, in connect
    self._conn = self.get_connection()
                 ^^^^^^^^^^^^^^^^^^^^^
  File "apps/frappe/frappe/database/mariadb/database.py", line 98, in get_connection
    conn = self._get_connection()
           ^^^^^^^^^^^^^^^^^^^^^^
  File "apps/frappe/frappe/database/mariadb/database.py", line 104, in _get_connection
    return self.create_connection()
           ^^^^^^^^^^^^^^^^^^^^^^^^
  File "apps/frappe/frappe/database/mariadb/database.py", line 107, in create_connection
    return pymysql.connect(**self.get_connection_settings())
           ^^^^^^^^^^^^^^^^^^^^^^^^^^^^^^^^^^^^^^^^^^^^^^^^^
  File "env/lib/python3.11/site-packages/pymysql/connections.py", line 352, in __init__
    self.connect()
  File "env/lib/python3.11/site-packages/pymysql/connections.py", line 636, in connect
    self._request_authentication()
  File "env/lib/python3.11/site-packages/pymysql/connections.py", line 911, in _request_authentication
    auth_packet = self._read_packet()
                  ^^^^^^^^^^^^^^^^^^^
  File "env/lib/python3.11/site-packages/pymysql/connections.py", line 729, in _read_packet
    packet.raise_for_error()
  File "env/lib/python3.11/site-packages/pymysql/protocol.py", line 221, in raise_for_error
    err.raise_mysql_exception(self._data)
  File "env/lib/python3.11/site-packages/pymysql/err.py", line 143, in raise_mysql_exception
    raise errorclass(errno, errval)
pymysql.err.OperationalError: (1049, "Unknown database '_9b8e683170b398ec'")

2023-11-14 13:14:15,948 ERROR scheduler Exception in Enqueue Events for Site srdc.local
Traceback (most recent call last):
  File "apps/frappe/frappe/utils/scheduler.py", line 75, in enqueue_events_for_site
    if is_scheduler_inactive():
       ^^^^^^^^^^^^^^^^^^^^^^^
  File "apps/frappe/frappe/utils/scheduler.py", line 114, in is_scheduler_inactive
    if is_scheduler_disabled(verbose=verbose):
       ^^^^^^^^^^^^^^^^^^^^^^^^^^^^^^^^^^^^^^
  File "apps/frappe/frappe/utils/scheduler.py", line 127, in is_scheduler_disabled
    frappe.db.get_single_value("System Settings", "enable_scheduler")
  File "apps/frappe/frappe/database/database.py", line 786, in get_single_value
    ).run()
      ^^^^^
  File "apps/frappe/frappe/query_builder/utils.py", line 87, in execute_query
    result = frappe.db.sql(query, params, *args, **kwargs)  # nosemgrep
             ^^^^^^^^^^^^^^^^^^^^^^^^^^^^^^^^^^^^^^^^^^^^^
  File "apps/frappe/frappe/database/database.py", line 201, in sql
    self.connect()
  File "apps/frappe/frappe/database/database.py", line 115, in connect
    self._conn = self.get_connection()
                 ^^^^^^^^^^^^^^^^^^^^^
  File "apps/frappe/frappe/database/mariadb/database.py", line 98, in get_connection
    conn = self._get_connection()
           ^^^^^^^^^^^^^^^^^^^^^^
  File "apps/frappe/frappe/database/mariadb/database.py", line 104, in _get_connection
    return self.create_connection()
           ^^^^^^^^^^^^^^^^^^^^^^^^
  File "apps/frappe/frappe/database/mariadb/database.py", line 107, in create_connection
    return pymysql.connect(**self.get_connection_settings())
           ^^^^^^^^^^^^^^^^^^^^^^^^^^^^^^^^^^^^^^^^^^^^^^^^^
  File "env/lib/python3.11/site-packages/pymysql/connections.py", line 352, in __init__
    self.connect()
  File "env/lib/python3.11/site-packages/pymysql/connections.py", line 636, in connect
    self._request_authentication()
  File "env/lib/python3.11/site-packages/pymysql/connections.py", line 911, in _request_authentication
    auth_packet = self._read_packet()
                  ^^^^^^^^^^^^^^^^^^^
  File "env/lib/python3.11/site-packages/pymysql/connections.py", line 729, in _read_packet
    packet.raise_for_error()
  File "env/lib/python3.11/site-packages/pymysql/protocol.py", line 221, in raise_for_error
    err.raise_mysql_exception(self._data)
  File "env/lib/python3.11/site-packages/pymysql/err.py", line 143, in raise_mysql_exception
    raise errorclass(errno, errval)
pymysql.err.OperationalError: (1698, "Access denied for user 'srdc_local'@'localhost'")

2023-11-14 13:30:26,829 ERROR scheduler Exception in Enqueue Events for Site srdc.local
Traceback (most recent call last):
  File "apps/frappe/frappe/utils/scheduler.py", line 75, in enqueue_events_for_site
    if is_scheduler_inactive():
       ^^^^^^^^^^^^^^^^^^^^^^^
  File "apps/frappe/frappe/utils/scheduler.py", line 114, in is_scheduler_inactive
    if is_scheduler_disabled(verbose=verbose):
       ^^^^^^^^^^^^^^^^^^^^^^^^^^^^^^^^^^^^^^
  File "apps/frappe/frappe/utils/scheduler.py", line 127, in is_scheduler_disabled
    frappe.db.get_single_value("System Settings", "enable_scheduler")
  File "apps/frappe/frappe/database/database.py", line 786, in get_single_value
    ).run()
      ^^^^^
  File "apps/frappe/frappe/query_builder/utils.py", line 87, in execute_query
    result = frappe.db.sql(query, params, *args, **kwargs)  # nosemgrep
             ^^^^^^^^^^^^^^^^^^^^^^^^^^^^^^^^^^^^^^^^^^^^^
  File "apps/frappe/frappe/database/database.py", line 201, in sql
    self.connect()
  File "apps/frappe/frappe/database/database.py", line 115, in connect
    self._conn = self.get_connection()
                 ^^^^^^^^^^^^^^^^^^^^^
  File "apps/frappe/frappe/database/mariadb/database.py", line 98, in get_connection
    conn = self._get_connection()
           ^^^^^^^^^^^^^^^^^^^^^^
  File "apps/frappe/frappe/database/mariadb/database.py", line 104, in _get_connection
    return self.create_connection()
           ^^^^^^^^^^^^^^^^^^^^^^^^
  File "apps/frappe/frappe/database/mariadb/database.py", line 107, in create_connection
    return pymysql.connect(**self.get_connection_settings())
           ^^^^^^^^^^^^^^^^^^^^^^^^^^^^^^^^^^^^^^^^^^^^^^^^^
  File "env/lib/python3.11/site-packages/pymysql/connections.py", line 352, in __init__
    self.connect()
  File "env/lib/python3.11/site-packages/pymysql/connections.py", line 636, in connect
    self._request_authentication()
  File "env/lib/python3.11/site-packages/pymysql/connections.py", line 911, in _request_authentication
    auth_packet = self._read_packet()
                  ^^^^^^^^^^^^^^^^^^^
  File "env/lib/python3.11/site-packages/pymysql/connections.py", line 729, in _read_packet
    packet.raise_for_error()
  File "env/lib/python3.11/site-packages/pymysql/protocol.py", line 221, in raise_for_error
    err.raise_mysql_exception(self._data)
  File "env/lib/python3.11/site-packages/pymysql/err.py", line 143, in raise_mysql_exception
    raise errorclass(errno, errval)
pymysql.err.OperationalError: (1049, "Unknown database '_3f14d08a0477f193'")

2023-11-14 13:30:26,831 ERROR scheduler Exception in Enqueue Events for Site erp.srdc.io
Traceback (most recent call last):
  File "apps/frappe/frappe/utils/scheduler.py", line 75, in enqueue_events_for_site
    if is_scheduler_inactive():
       ^^^^^^^^^^^^^^^^^^^^^^^
  File "apps/frappe/frappe/utils/scheduler.py", line 114, in is_scheduler_inactive
    if is_scheduler_disabled(verbose=verbose):
       ^^^^^^^^^^^^^^^^^^^^^^^^^^^^^^^^^^^^^^
  File "apps/frappe/frappe/utils/scheduler.py", line 127, in is_scheduler_disabled
    frappe.db.get_single_value("System Settings", "enable_scheduler")
  File "apps/frappe/frappe/database/database.py", line 786, in get_single_value
    ).run()
      ^^^^^
  File "apps/frappe/frappe/query_builder/utils.py", line 87, in execute_query
    result = frappe.db.sql(query, params, *args, **kwargs)  # nosemgrep
             ^^^^^^^^^^^^^^^^^^^^^^^^^^^^^^^^^^^^^^^^^^^^^
  File "apps/frappe/frappe/database/database.py", line 201, in sql
    self.connect()
  File "apps/frappe/frappe/database/database.py", line 115, in connect
    self._conn = self.get_connection()
                 ^^^^^^^^^^^^^^^^^^^^^
  File "apps/frappe/frappe/database/mariadb/database.py", line 98, in get_connection
    conn = self._get_connection()
           ^^^^^^^^^^^^^^^^^^^^^^
  File "apps/frappe/frappe/database/mariadb/database.py", line 104, in _get_connection
    return self.create_connection()
           ^^^^^^^^^^^^^^^^^^^^^^^^
  File "apps/frappe/frappe/database/mariadb/database.py", line 107, in create_connection
    return pymysql.connect(**self.get_connection_settings())
           ^^^^^^^^^^^^^^^^^^^^^^^^^^^^^^^^^^^^^^^^^^^^^^^^^
  File "env/lib/python3.11/site-packages/pymysql/connections.py", line 352, in __init__
    self.connect()
  File "env/lib/python3.11/site-packages/pymysql/connections.py", line 636, in connect
    self._request_authentication()
  File "env/lib/python3.11/site-packages/pymysql/connections.py", line 911, in _request_authentication
    auth_packet = self._read_packet()
                  ^^^^^^^^^^^^^^^^^^^
  File "env/lib/python3.11/site-packages/pymysql/connections.py", line 729, in _read_packet
    packet.raise_for_error()
  File "env/lib/python3.11/site-packages/pymysql/protocol.py", line 221, in raise_for_error
    err.raise_mysql_exception(self._data)
  File "env/lib/python3.11/site-packages/pymysql/err.py", line 143, in raise_mysql_exception
    raise errorclass(errno, errval)
pymysql.err.OperationalError: (1049, "Unknown database '_9b8e683170b398ec'")

2023-11-14 13:32:44,427 ERROR scheduler Exception in Enqueue Events for Site erp.srdc.io
Traceback (most recent call last):
  File "apps/frappe/frappe/utils/scheduler.py", line 75, in enqueue_events_for_site
    if is_scheduler_inactive():
       ^^^^^^^^^^^^^^^^^^^^^^^
  File "apps/frappe/frappe/utils/scheduler.py", line 114, in is_scheduler_inactive
    if is_scheduler_disabled(verbose=verbose):
       ^^^^^^^^^^^^^^^^^^^^^^^^^^^^^^^^^^^^^^
  File "apps/frappe/frappe/utils/scheduler.py", line 127, in is_scheduler_disabled
    frappe.db.get_single_value("System Settings", "enable_scheduler")
  File "apps/frappe/frappe/database/database.py", line 786, in get_single_value
    ).run()
      ^^^^^
  File "apps/frappe/frappe/query_builder/utils.py", line 87, in execute_query
    result = frappe.db.sql(query, params, *args, **kwargs)  # nosemgrep
             ^^^^^^^^^^^^^^^^^^^^^^^^^^^^^^^^^^^^^^^^^^^^^
  File "apps/frappe/frappe/database/database.py", line 201, in sql
    self.connect()
  File "apps/frappe/frappe/database/database.py", line 115, in connect
    self._conn = self.get_connection()
                 ^^^^^^^^^^^^^^^^^^^^^
  File "apps/frappe/frappe/database/mariadb/database.py", line 98, in get_connection
    conn = self._get_connection()
           ^^^^^^^^^^^^^^^^^^^^^^
  File "apps/frappe/frappe/database/mariadb/database.py", line 104, in _get_connection
    return self.create_connection()
           ^^^^^^^^^^^^^^^^^^^^^^^^
  File "apps/frappe/frappe/database/mariadb/database.py", line 107, in create_connection
    return pymysql.connect(**self.get_connection_settings())
           ^^^^^^^^^^^^^^^^^^^^^^^^^^^^^^^^^^^^^^^^^^^^^^^^^
  File "env/lib/python3.11/site-packages/pymysql/connections.py", line 352, in __init__
    self.connect()
  File "env/lib/python3.11/site-packages/pymysql/connections.py", line 636, in connect
    self._request_authentication()
  File "env/lib/python3.11/site-packages/pymysql/connections.py", line 911, in _request_authentication
    auth_packet = self._read_packet()
                  ^^^^^^^^^^^^^^^^^^^
  File "env/lib/python3.11/site-packages/pymysql/connections.py", line 729, in _read_packet
    packet.raise_for_error()
  File "env/lib/python3.11/site-packages/pymysql/protocol.py", line 221, in raise_for_error
    err.raise_mysql_exception(self._data)
  File "env/lib/python3.11/site-packages/pymysql/err.py", line 143, in raise_mysql_exception
    raise errorclass(errno, errval)
pymysql.err.OperationalError: (1049, "Unknown database '_9b8e683170b398ec'")

2023-11-14 13:32:44,429 ERROR scheduler Exception in Enqueue Events for Site srdc.local
Traceback (most recent call last):
  File "apps/frappe/frappe/utils/scheduler.py", line 75, in enqueue_events_for_site
    if is_scheduler_inactive():
       ^^^^^^^^^^^^^^^^^^^^^^^
  File "apps/frappe/frappe/utils/scheduler.py", line 114, in is_scheduler_inactive
    if is_scheduler_disabled(verbose=verbose):
       ^^^^^^^^^^^^^^^^^^^^^^^^^^^^^^^^^^^^^^
  File "apps/frappe/frappe/utils/scheduler.py", line 127, in is_scheduler_disabled
    frappe.db.get_single_value("System Settings", "enable_scheduler")
  File "apps/frappe/frappe/database/database.py", line 786, in get_single_value
    ).run()
      ^^^^^
  File "apps/frappe/frappe/query_builder/utils.py", line 87, in execute_query
    result = frappe.db.sql(query, params, *args, **kwargs)  # nosemgrep
             ^^^^^^^^^^^^^^^^^^^^^^^^^^^^^^^^^^^^^^^^^^^^^
  File "apps/frappe/frappe/database/database.py", line 220, in sql
    self._cursor.execute(query, values)
  File "env/lib/python3.11/site-packages/pymysql/cursors.py", line 158, in execute
    result = self._query(query)
             ^^^^^^^^^^^^^^^^^^
  File "env/lib/python3.11/site-packages/pymysql/cursors.py", line 325, in _query
    conn.query(q)
  File "env/lib/python3.11/site-packages/pymysql/connections.py", line 549, in query
    self._affected_rows = self._read_query_result(unbuffered=unbuffered)
                          ^^^^^^^^^^^^^^^^^^^^^^^^^^^^^^^^^^^^^^^^^^^^^^
  File "env/lib/python3.11/site-packages/pymysql/connections.py", line 779, in _read_query_result
    result.read()
  File "env/lib/python3.11/site-packages/pymysql/connections.py", line 1157, in read
    first_packet = self.connection._read_packet()
                   ^^^^^^^^^^^^^^^^^^^^^^^^^^^^^^
  File "env/lib/python3.11/site-packages/pymysql/connections.py", line 729, in _read_packet
    packet.raise_for_error()
  File "env/lib/python3.11/site-packages/pymysql/protocol.py", line 221, in raise_for_error
    err.raise_mysql_exception(self._data)
  File "env/lib/python3.11/site-packages/pymysql/err.py", line 143, in raise_mysql_exception
    raise errorclass(errno, errval)
pymysql.err.ProgrammingError: (1146, "Table '_3f14d08a0477f193.tabSingles' doesn't exist")

2023-11-14 13:33:44,445 ERROR scheduler Exception in Enqueue Events for Site srdc.local
Traceback (most recent call last):
  File "apps/frappe/frappe/utils/scheduler.py", line 75, in enqueue_events_for_site
    if is_scheduler_inactive():
       ^^^^^^^^^^^^^^^^^^^^^^^
  File "apps/frappe/frappe/utils/scheduler.py", line 114, in is_scheduler_inactive
    if is_scheduler_disabled(verbose=verbose):
       ^^^^^^^^^^^^^^^^^^^^^^^^^^^^^^^^^^^^^^
  File "apps/frappe/frappe/utils/scheduler.py", line 127, in is_scheduler_disabled
    frappe.db.get_single_value("System Settings", "enable_scheduler")
  File "apps/frappe/frappe/database/database.py", line 786, in get_single_value
    ).run()
      ^^^^^
  File "apps/frappe/frappe/query_builder/utils.py", line 87, in execute_query
    result = frappe.db.sql(query, params, *args, **kwargs)  # nosemgrep
             ^^^^^^^^^^^^^^^^^^^^^^^^^^^^^^^^^^^^^^^^^^^^^
  File "apps/frappe/frappe/database/database.py", line 220, in sql
    self._cursor.execute(query, values)
  File "env/lib/python3.11/site-packages/pymysql/cursors.py", line 158, in execute
    result = self._query(query)
             ^^^^^^^^^^^^^^^^^^
  File "env/lib/python3.11/site-packages/pymysql/cursors.py", line 325, in _query
    conn.query(q)
  File "env/lib/python3.11/site-packages/pymysql/connections.py", line 549, in query
    self._affected_rows = self._read_query_result(unbuffered=unbuffered)
                          ^^^^^^^^^^^^^^^^^^^^^^^^^^^^^^^^^^^^^^^^^^^^^^
  File "env/lib/python3.11/site-packages/pymysql/connections.py", line 779, in _read_query_result
    result.read()
  File "env/lib/python3.11/site-packages/pymysql/connections.py", line 1157, in read
    first_packet = self.connection._read_packet()
                   ^^^^^^^^^^^^^^^^^^^^^^^^^^^^^^
  File "env/lib/python3.11/site-packages/pymysql/connections.py", line 729, in _read_packet
    packet.raise_for_error()
  File "env/lib/python3.11/site-packages/pymysql/protocol.py", line 221, in raise_for_error
    err.raise_mysql_exception(self._data)
  File "env/lib/python3.11/site-packages/pymysql/err.py", line 143, in raise_mysql_exception
    raise errorclass(errno, errval)
pymysql.err.ProgrammingError: (1146, "Table '_3f14d08a0477f193.tabSingles' doesn't exist")

2023-11-14 13:33:44,454 ERROR scheduler Exception in Enqueue Events for Site erp.srdc.io
Traceback (most recent call last):
  File "apps/frappe/frappe/utils/scheduler.py", line 75, in enqueue_events_for_site
    if is_scheduler_inactive():
       ^^^^^^^^^^^^^^^^^^^^^^^
  File "apps/frappe/frappe/utils/scheduler.py", line 114, in is_scheduler_inactive
    if is_scheduler_disabled(verbose=verbose):
       ^^^^^^^^^^^^^^^^^^^^^^^^^^^^^^^^^^^^^^
  File "apps/frappe/frappe/utils/scheduler.py", line 127, in is_scheduler_disabled
    frappe.db.get_single_value("System Settings", "enable_scheduler")
  File "apps/frappe/frappe/database/database.py", line 786, in get_single_value
    ).run()
      ^^^^^
  File "apps/frappe/frappe/query_builder/utils.py", line 87, in execute_query
    result = frappe.db.sql(query, params, *args, **kwargs)  # nosemgrep
             ^^^^^^^^^^^^^^^^^^^^^^^^^^^^^^^^^^^^^^^^^^^^^
  File "apps/frappe/frappe/database/database.py", line 201, in sql
    self.connect()
  File "apps/frappe/frappe/database/database.py", line 115, in connect
    self._conn = self.get_connection()
                 ^^^^^^^^^^^^^^^^^^^^^
  File "apps/frappe/frappe/database/mariadb/database.py", line 98, in get_connection
    conn = self._get_connection()
           ^^^^^^^^^^^^^^^^^^^^^^
  File "apps/frappe/frappe/database/mariadb/database.py", line 104, in _get_connection
    return self.create_connection()
           ^^^^^^^^^^^^^^^^^^^^^^^^
  File "apps/frappe/frappe/database/mariadb/database.py", line 107, in create_connection
    return pymysql.connect(**self.get_connection_settings())
           ^^^^^^^^^^^^^^^^^^^^^^^^^^^^^^^^^^^^^^^^^^^^^^^^^
  File "env/lib/python3.11/site-packages/pymysql/connections.py", line 352, in __init__
    self.connect()
  File "env/lib/python3.11/site-packages/pymysql/connections.py", line 636, in connect
    self._request_authentication()
  File "env/lib/python3.11/site-packages/pymysql/connections.py", line 911, in _request_authentication
    auth_packet = self._read_packet()
                  ^^^^^^^^^^^^^^^^^^^
  File "env/lib/python3.11/site-packages/pymysql/connections.py", line 729, in _read_packet
    packet.raise_for_error()
  File "env/lib/python3.11/site-packages/pymysql/protocol.py", line 221, in raise_for_error
    err.raise_mysql_exception(self._data)
  File "env/lib/python3.11/site-packages/pymysql/err.py", line 143, in raise_mysql_exception
    raise errorclass(errno, errval)
pymysql.err.OperationalError: (1049, "Unknown database '_9b8e683170b398ec'")

2023-11-14 13:34:44,459 ERROR scheduler Exception in Enqueue Events for Site erp.srdc.io
Traceback (most recent call last):
  File "apps/frappe/frappe/utils/scheduler.py", line 75, in enqueue_events_for_site
    if is_scheduler_inactive():
       ^^^^^^^^^^^^^^^^^^^^^^^
  File "apps/frappe/frappe/utils/scheduler.py", line 114, in is_scheduler_inactive
    if is_scheduler_disabled(verbose=verbose):
       ^^^^^^^^^^^^^^^^^^^^^^^^^^^^^^^^^^^^^^
  File "apps/frappe/frappe/utils/scheduler.py", line 127, in is_scheduler_disabled
    frappe.db.get_single_value("System Settings", "enable_scheduler")
  File "apps/frappe/frappe/database/database.py", line 786, in get_single_value
    ).run()
      ^^^^^
  File "apps/frappe/frappe/query_builder/utils.py", line 87, in execute_query
    result = frappe.db.sql(query, params, *args, **kwargs)  # nosemgrep
             ^^^^^^^^^^^^^^^^^^^^^^^^^^^^^^^^^^^^^^^^^^^^^
  File "apps/frappe/frappe/database/database.py", line 201, in sql
    self.connect()
  File "apps/frappe/frappe/database/database.py", line 115, in connect
    self._conn = self.get_connection()
                 ^^^^^^^^^^^^^^^^^^^^^
  File "apps/frappe/frappe/database/mariadb/database.py", line 98, in get_connection
    conn = self._get_connection()
           ^^^^^^^^^^^^^^^^^^^^^^
  File "apps/frappe/frappe/database/mariadb/database.py", line 104, in _get_connection
    return self.create_connection()
           ^^^^^^^^^^^^^^^^^^^^^^^^
  File "apps/frappe/frappe/database/mariadb/database.py", line 107, in create_connection
    return pymysql.connect(**self.get_connection_settings())
           ^^^^^^^^^^^^^^^^^^^^^^^^^^^^^^^^^^^^^^^^^^^^^^^^^
  File "env/lib/python3.11/site-packages/pymysql/connections.py", line 352, in __init__
    self.connect()
  File "env/lib/python3.11/site-packages/pymysql/connections.py", line 636, in connect
    self._request_authentication()
  File "env/lib/python3.11/site-packages/pymysql/connections.py", line 911, in _request_authentication
    auth_packet = self._read_packet()
                  ^^^^^^^^^^^^^^^^^^^
  File "env/lib/python3.11/site-packages/pymysql/connections.py", line 729, in _read_packet
    packet.raise_for_error()
  File "env/lib/python3.11/site-packages/pymysql/protocol.py", line 221, in raise_for_error
    err.raise_mysql_exception(self._data)
  File "env/lib/python3.11/site-packages/pymysql/err.py", line 143, in raise_mysql_exception
    raise errorclass(errno, errval)
pymysql.err.OperationalError: (1049, "Unknown database '_9b8e683170b398ec'")

2023-11-14 13:34:44,463 ERROR scheduler Exception in Enqueue Events for Site srdc.local
Traceback (most recent call last):
  File "apps/frappe/frappe/utils/scheduler.py", line 75, in enqueue_events_for_site
    if is_scheduler_inactive():
       ^^^^^^^^^^^^^^^^^^^^^^^
  File "apps/frappe/frappe/utils/scheduler.py", line 114, in is_scheduler_inactive
    if is_scheduler_disabled(verbose=verbose):
       ^^^^^^^^^^^^^^^^^^^^^^^^^^^^^^^^^^^^^^
  File "apps/frappe/frappe/utils/scheduler.py", line 127, in is_scheduler_disabled
    frappe.db.get_single_value("System Settings", "enable_scheduler")
  File "apps/frappe/frappe/database/database.py", line 786, in get_single_value
    ).run()
      ^^^^^
  File "apps/frappe/frappe/query_builder/utils.py", line 87, in execute_query
    result = frappe.db.sql(query, params, *args, **kwargs)  # nosemgrep
             ^^^^^^^^^^^^^^^^^^^^^^^^^^^^^^^^^^^^^^^^^^^^^
  File "apps/frappe/frappe/database/database.py", line 220, in sql
    self._cursor.execute(query, values)
  File "env/lib/python3.11/site-packages/pymysql/cursors.py", line 158, in execute
    result = self._query(query)
             ^^^^^^^^^^^^^^^^^^
  File "env/lib/python3.11/site-packages/pymysql/cursors.py", line 325, in _query
    conn.query(q)
  File "env/lib/python3.11/site-packages/pymysql/connections.py", line 549, in query
    self._affected_rows = self._read_query_result(unbuffered=unbuffered)
                          ^^^^^^^^^^^^^^^^^^^^^^^^^^^^^^^^^^^^^^^^^^^^^^
  File "env/lib/python3.11/site-packages/pymysql/connections.py", line 779, in _read_query_result
    result.read()
  File "env/lib/python3.11/site-packages/pymysql/connections.py", line 1157, in read
    first_packet = self.connection._read_packet()
                   ^^^^^^^^^^^^^^^^^^^^^^^^^^^^^^
  File "env/lib/python3.11/site-packages/pymysql/connections.py", line 729, in _read_packet
    packet.raise_for_error()
  File "env/lib/python3.11/site-packages/pymysql/protocol.py", line 221, in raise_for_error
    err.raise_mysql_exception(self._data)
  File "env/lib/python3.11/site-packages/pymysql/err.py", line 143, in raise_mysql_exception
    raise errorclass(errno, errval)
pymysql.err.ProgrammingError: (1146, "Table '_3f14d08a0477f193.tabSingles' doesn't exist")

2023-11-14 13:35:44,511 ERROR scheduler Exception in Enqueue Events for Site erp.srdc.io
Traceback (most recent call last):
  File "apps/frappe/frappe/utils/scheduler.py", line 75, in enqueue_events_for_site
    if is_scheduler_inactive():
       ^^^^^^^^^^^^^^^^^^^^^^^
  File "apps/frappe/frappe/utils/scheduler.py", line 114, in is_scheduler_inactive
    if is_scheduler_disabled(verbose=verbose):
       ^^^^^^^^^^^^^^^^^^^^^^^^^^^^^^^^^^^^^^
  File "apps/frappe/frappe/utils/scheduler.py", line 127, in is_scheduler_disabled
    frappe.db.get_single_value("System Settings", "enable_scheduler")
  File "apps/frappe/frappe/database/database.py", line 786, in get_single_value
    ).run()
      ^^^^^
  File "apps/frappe/frappe/query_builder/utils.py", line 87, in execute_query
    result = frappe.db.sql(query, params, *args, **kwargs)  # nosemgrep
             ^^^^^^^^^^^^^^^^^^^^^^^^^^^^^^^^^^^^^^^^^^^^^
  File "apps/frappe/frappe/database/database.py", line 201, in sql
    self.connect()
  File "apps/frappe/frappe/database/database.py", line 115, in connect
    self._conn = self.get_connection()
                 ^^^^^^^^^^^^^^^^^^^^^
  File "apps/frappe/frappe/database/mariadb/database.py", line 98, in get_connection
    conn = self._get_connection()
           ^^^^^^^^^^^^^^^^^^^^^^
  File "apps/frappe/frappe/database/mariadb/database.py", line 104, in _get_connection
    return self.create_connection()
           ^^^^^^^^^^^^^^^^^^^^^^^^
  File "apps/frappe/frappe/database/mariadb/database.py", line 107, in create_connection
    return pymysql.connect(**self.get_connection_settings())
           ^^^^^^^^^^^^^^^^^^^^^^^^^^^^^^^^^^^^^^^^^^^^^^^^^
  File "env/lib/python3.11/site-packages/pymysql/connections.py", line 352, in __init__
    self.connect()
  File "env/lib/python3.11/site-packages/pymysql/connections.py", line 636, in connect
    self._request_authentication()
  File "env/lib/python3.11/site-packages/pymysql/connections.py", line 911, in _request_authentication
    auth_packet = self._read_packet()
                  ^^^^^^^^^^^^^^^^^^^
  File "env/lib/python3.11/site-packages/pymysql/connections.py", line 729, in _read_packet
    packet.raise_for_error()
  File "env/lib/python3.11/site-packages/pymysql/protocol.py", line 221, in raise_for_error
    err.raise_mysql_exception(self._data)
  File "env/lib/python3.11/site-packages/pymysql/err.py", line 143, in raise_mysql_exception
    raise errorclass(errno, errval)
pymysql.err.OperationalError: (1049, "Unknown database '_9b8e683170b398ec'")

2023-11-14 13:35:44,524 ERROR scheduler Exception in Enqueue Events for Site srdc.local
Traceback (most recent call last):
  File "apps/frappe/frappe/utils/scheduler.py", line 75, in enqueue_events_for_site
    if is_scheduler_inactive():
       ^^^^^^^^^^^^^^^^^^^^^^^
  File "apps/frappe/frappe/utils/scheduler.py", line 114, in is_scheduler_inactive
    if is_scheduler_disabled(verbose=verbose):
       ^^^^^^^^^^^^^^^^^^^^^^^^^^^^^^^^^^^^^^
  File "apps/frappe/frappe/utils/scheduler.py", line 127, in is_scheduler_disabled
    frappe.db.get_single_value("System Settings", "enable_scheduler")
  File "apps/frappe/frappe/database/database.py", line 786, in get_single_value
    ).run()
      ^^^^^
  File "apps/frappe/frappe/query_builder/utils.py", line 87, in execute_query
    result = frappe.db.sql(query, params, *args, **kwargs)  # nosemgrep
             ^^^^^^^^^^^^^^^^^^^^^^^^^^^^^^^^^^^^^^^^^^^^^
  File "apps/frappe/frappe/database/database.py", line 220, in sql
    self._cursor.execute(query, values)
  File "env/lib/python3.11/site-packages/pymysql/cursors.py", line 158, in execute
    result = self._query(query)
             ^^^^^^^^^^^^^^^^^^
  File "env/lib/python3.11/site-packages/pymysql/cursors.py", line 325, in _query
    conn.query(q)
  File "env/lib/python3.11/site-packages/pymysql/connections.py", line 549, in query
    self._affected_rows = self._read_query_result(unbuffered=unbuffered)
                          ^^^^^^^^^^^^^^^^^^^^^^^^^^^^^^^^^^^^^^^^^^^^^^
  File "env/lib/python3.11/site-packages/pymysql/connections.py", line 779, in _read_query_result
    result.read()
  File "env/lib/python3.11/site-packages/pymysql/connections.py", line 1157, in read
    first_packet = self.connection._read_packet()
                   ^^^^^^^^^^^^^^^^^^^^^^^^^^^^^^
  File "env/lib/python3.11/site-packages/pymysql/connections.py", line 729, in _read_packet
    packet.raise_for_error()
  File "env/lib/python3.11/site-packages/pymysql/protocol.py", line 221, in raise_for_error
    err.raise_mysql_exception(self._data)
  File "env/lib/python3.11/site-packages/pymysql/err.py", line 143, in raise_mysql_exception
    raise errorclass(errno, errval)
pymysql.err.ProgrammingError: (1146, "Table '_3f14d08a0477f193.tabSingles' doesn't exist")

2023-11-14 13:36:44,542 ERROR scheduler Exception in Enqueue Events for Site erp.srdc.io
Traceback (most recent call last):
  File "apps/frappe/frappe/utils/scheduler.py", line 75, in enqueue_events_for_site
    if is_scheduler_inactive():
       ^^^^^^^^^^^^^^^^^^^^^^^
  File "apps/frappe/frappe/utils/scheduler.py", line 114, in is_scheduler_inactive
    if is_scheduler_disabled(verbose=verbose):
       ^^^^^^^^^^^^^^^^^^^^^^^^^^^^^^^^^^^^^^
  File "apps/frappe/frappe/utils/scheduler.py", line 127, in is_scheduler_disabled
    frappe.db.get_single_value("System Settings", "enable_scheduler")
  File "apps/frappe/frappe/database/database.py", line 786, in get_single_value
    ).run()
      ^^^^^
  File "apps/frappe/frappe/query_builder/utils.py", line 87, in execute_query
    result = frappe.db.sql(query, params, *args, **kwargs)  # nosemgrep
             ^^^^^^^^^^^^^^^^^^^^^^^^^^^^^^^^^^^^^^^^^^^^^
  File "apps/frappe/frappe/database/database.py", line 201, in sql
    self.connect()
  File "apps/frappe/frappe/database/database.py", line 115, in connect
    self._conn = self.get_connection()
                 ^^^^^^^^^^^^^^^^^^^^^
  File "apps/frappe/frappe/database/mariadb/database.py", line 98, in get_connection
    conn = self._get_connection()
           ^^^^^^^^^^^^^^^^^^^^^^
  File "apps/frappe/frappe/database/mariadb/database.py", line 104, in _get_connection
    return self.create_connection()
           ^^^^^^^^^^^^^^^^^^^^^^^^
  File "apps/frappe/frappe/database/mariadb/database.py", line 107, in create_connection
    return pymysql.connect(**self.get_connection_settings())
           ^^^^^^^^^^^^^^^^^^^^^^^^^^^^^^^^^^^^^^^^^^^^^^^^^
  File "env/lib/python3.11/site-packages/pymysql/connections.py", line 352, in __init__
    self.connect()
  File "env/lib/python3.11/site-packages/pymysql/connections.py", line 636, in connect
    self._request_authentication()
  File "env/lib/python3.11/site-packages/pymysql/connections.py", line 911, in _request_authentication
    auth_packet = self._read_packet()
                  ^^^^^^^^^^^^^^^^^^^
  File "env/lib/python3.11/site-packages/pymysql/connections.py", line 729, in _read_packet
    packet.raise_for_error()
  File "env/lib/python3.11/site-packages/pymysql/protocol.py", line 221, in raise_for_error
    err.raise_mysql_exception(self._data)
  File "env/lib/python3.11/site-packages/pymysql/err.py", line 143, in raise_mysql_exception
    raise errorclass(errno, errval)
pymysql.err.OperationalError: (1049, "Unknown database '_9b8e683170b398ec'")

2023-11-14 13:36:44,552 ERROR scheduler Exception in Enqueue Events for Site srdc.local
Traceback (most recent call last):
  File "apps/frappe/frappe/utils/scheduler.py", line 75, in enqueue_events_for_site
    if is_scheduler_inactive():
       ^^^^^^^^^^^^^^^^^^^^^^^
  File "apps/frappe/frappe/utils/scheduler.py", line 114, in is_scheduler_inactive
    if is_scheduler_disabled(verbose=verbose):
       ^^^^^^^^^^^^^^^^^^^^^^^^^^^^^^^^^^^^^^
  File "apps/frappe/frappe/utils/scheduler.py", line 127, in is_scheduler_disabled
    frappe.db.get_single_value("System Settings", "enable_scheduler")
  File "apps/frappe/frappe/database/database.py", line 786, in get_single_value
    ).run()
      ^^^^^
  File "apps/frappe/frappe/query_builder/utils.py", line 87, in execute_query
    result = frappe.db.sql(query, params, *args, **kwargs)  # nosemgrep
             ^^^^^^^^^^^^^^^^^^^^^^^^^^^^^^^^^^^^^^^^^^^^^
  File "apps/frappe/frappe/database/database.py", line 220, in sql
    self._cursor.execute(query, values)
  File "env/lib/python3.11/site-packages/pymysql/cursors.py", line 158, in execute
    result = self._query(query)
             ^^^^^^^^^^^^^^^^^^
  File "env/lib/python3.11/site-packages/pymysql/cursors.py", line 325, in _query
    conn.query(q)
  File "env/lib/python3.11/site-packages/pymysql/connections.py", line 549, in query
    self._affected_rows = self._read_query_result(unbuffered=unbuffered)
                          ^^^^^^^^^^^^^^^^^^^^^^^^^^^^^^^^^^^^^^^^^^^^^^
  File "env/lib/python3.11/site-packages/pymysql/connections.py", line 779, in _read_query_result
    result.read()
  File "env/lib/python3.11/site-packages/pymysql/connections.py", line 1157, in read
    first_packet = self.connection._read_packet()
                   ^^^^^^^^^^^^^^^^^^^^^^^^^^^^^^
  File "env/lib/python3.11/site-packages/pymysql/connections.py", line 729, in _read_packet
    packet.raise_for_error()
  File "env/lib/python3.11/site-packages/pymysql/protocol.py", line 221, in raise_for_error
    err.raise_mysql_exception(self._data)
  File "env/lib/python3.11/site-packages/pymysql/err.py", line 143, in raise_mysql_exception
    raise errorclass(errno, errval)
pymysql.err.ProgrammingError: (1146, "Table '_3f14d08a0477f193.tabSingles' doesn't exist")

2023-11-14 13:37:44,556 ERROR scheduler Exception in Enqueue Events for Site erp.srdc.io
Traceback (most recent call last):
  File "apps/frappe/frappe/utils/scheduler.py", line 75, in enqueue_events_for_site
    if is_scheduler_inactive():
       ^^^^^^^^^^^^^^^^^^^^^^^
  File "apps/frappe/frappe/utils/scheduler.py", line 114, in is_scheduler_inactive
    if is_scheduler_disabled(verbose=verbose):
       ^^^^^^^^^^^^^^^^^^^^^^^^^^^^^^^^^^^^^^
  File "apps/frappe/frappe/utils/scheduler.py", line 127, in is_scheduler_disabled
    frappe.db.get_single_value("System Settings", "enable_scheduler")
  File "apps/frappe/frappe/database/database.py", line 786, in get_single_value
    ).run()
      ^^^^^
  File "apps/frappe/frappe/query_builder/utils.py", line 87, in execute_query
    result = frappe.db.sql(query, params, *args, **kwargs)  # nosemgrep
             ^^^^^^^^^^^^^^^^^^^^^^^^^^^^^^^^^^^^^^^^^^^^^
  File "apps/frappe/frappe/database/database.py", line 201, in sql
    self.connect()
  File "apps/frappe/frappe/database/database.py", line 115, in connect
    self._conn = self.get_connection()
                 ^^^^^^^^^^^^^^^^^^^^^
  File "apps/frappe/frappe/database/mariadb/database.py", line 98, in get_connection
    conn = self._get_connection()
           ^^^^^^^^^^^^^^^^^^^^^^
  File "apps/frappe/frappe/database/mariadb/database.py", line 104, in _get_connection
    return self.create_connection()
           ^^^^^^^^^^^^^^^^^^^^^^^^
  File "apps/frappe/frappe/database/mariadb/database.py", line 107, in create_connection
    return pymysql.connect(**self.get_connection_settings())
           ^^^^^^^^^^^^^^^^^^^^^^^^^^^^^^^^^^^^^^^^^^^^^^^^^
  File "env/lib/python3.11/site-packages/pymysql/connections.py", line 352, in __init__
    self.connect()
  File "env/lib/python3.11/site-packages/pymysql/connections.py", line 636, in connect
    self._request_authentication()
  File "env/lib/python3.11/site-packages/pymysql/connections.py", line 911, in _request_authentication
    auth_packet = self._read_packet()
                  ^^^^^^^^^^^^^^^^^^^
  File "env/lib/python3.11/site-packages/pymysql/connections.py", line 729, in _read_packet
    packet.raise_for_error()
  File "env/lib/python3.11/site-packages/pymysql/protocol.py", line 221, in raise_for_error
    err.raise_mysql_exception(self._data)
  File "env/lib/python3.11/site-packages/pymysql/err.py", line 143, in raise_mysql_exception
    raise errorclass(errno, errval)
pymysql.err.OperationalError: (1049, "Unknown database '_9b8e683170b398ec'")

2023-11-14 13:37:44,558 ERROR scheduler Exception in Enqueue Events for Site srdc.local
Traceback (most recent call last):
  File "apps/frappe/frappe/utils/scheduler.py", line 75, in enqueue_events_for_site
    if is_scheduler_inactive():
       ^^^^^^^^^^^^^^^^^^^^^^^
  File "apps/frappe/frappe/utils/scheduler.py", line 114, in is_scheduler_inactive
    if is_scheduler_disabled(verbose=verbose):
       ^^^^^^^^^^^^^^^^^^^^^^^^^^^^^^^^^^^^^^
  File "apps/frappe/frappe/utils/scheduler.py", line 127, in is_scheduler_disabled
    frappe.db.get_single_value("System Settings", "enable_scheduler")
  File "apps/frappe/frappe/database/database.py", line 786, in get_single_value
    ).run()
      ^^^^^
  File "apps/frappe/frappe/query_builder/utils.py", line 87, in execute_query
    result = frappe.db.sql(query, params, *args, **kwargs)  # nosemgrep
             ^^^^^^^^^^^^^^^^^^^^^^^^^^^^^^^^^^^^^^^^^^^^^
  File "apps/frappe/frappe/database/database.py", line 220, in sql
    self._cursor.execute(query, values)
  File "env/lib/python3.11/site-packages/pymysql/cursors.py", line 158, in execute
    result = self._query(query)
             ^^^^^^^^^^^^^^^^^^
  File "env/lib/python3.11/site-packages/pymysql/cursors.py", line 325, in _query
    conn.query(q)
  File "env/lib/python3.11/site-packages/pymysql/connections.py", line 549, in query
    self._affected_rows = self._read_query_result(unbuffered=unbuffered)
                          ^^^^^^^^^^^^^^^^^^^^^^^^^^^^^^^^^^^^^^^^^^^^^^
  File "env/lib/python3.11/site-packages/pymysql/connections.py", line 779, in _read_query_result
    result.read()
  File "env/lib/python3.11/site-packages/pymysql/connections.py", line 1157, in read
    first_packet = self.connection._read_packet()
                   ^^^^^^^^^^^^^^^^^^^^^^^^^^^^^^
  File "env/lib/python3.11/site-packages/pymysql/connections.py", line 729, in _read_packet
    packet.raise_for_error()
  File "env/lib/python3.11/site-packages/pymysql/protocol.py", line 221, in raise_for_error
    err.raise_mysql_exception(self._data)
  File "env/lib/python3.11/site-packages/pymysql/err.py", line 143, in raise_mysql_exception
    raise errorclass(errno, errval)
pymysql.err.ProgrammingError: (1146, "Table '_3f14d08a0477f193.tabSingles' doesn't exist")

2023-11-14 13:38:44,589 ERROR scheduler Exception in Enqueue Events for Site srdc.local
Traceback (most recent call last):
  File "apps/frappe/frappe/utils/scheduler.py", line 75, in enqueue_events_for_site
    if is_scheduler_inactive():
       ^^^^^^^^^^^^^^^^^^^^^^^
  File "apps/frappe/frappe/utils/scheduler.py", line 114, in is_scheduler_inactive
    if is_scheduler_disabled(verbose=verbose):
       ^^^^^^^^^^^^^^^^^^^^^^^^^^^^^^^^^^^^^^
  File "apps/frappe/frappe/utils/scheduler.py", line 127, in is_scheduler_disabled
    frappe.db.get_single_value("System Settings", "enable_scheduler")
  File "apps/frappe/frappe/database/database.py", line 786, in get_single_value
    ).run()
      ^^^^^
  File "apps/frappe/frappe/query_builder/utils.py", line 87, in execute_query
    result = frappe.db.sql(query, params, *args, **kwargs)  # nosemgrep
             ^^^^^^^^^^^^^^^^^^^^^^^^^^^^^^^^^^^^^^^^^^^^^
  File "apps/frappe/frappe/database/database.py", line 220, in sql
    self._cursor.execute(query, values)
  File "env/lib/python3.11/site-packages/pymysql/cursors.py", line 158, in execute
    result = self._query(query)
             ^^^^^^^^^^^^^^^^^^
  File "env/lib/python3.11/site-packages/pymysql/cursors.py", line 325, in _query
    conn.query(q)
  File "env/lib/python3.11/site-packages/pymysql/connections.py", line 549, in query
    self._affected_rows = self._read_query_result(unbuffered=unbuffered)
                          ^^^^^^^^^^^^^^^^^^^^^^^^^^^^^^^^^^^^^^^^^^^^^^
  File "env/lib/python3.11/site-packages/pymysql/connections.py", line 779, in _read_query_result
    result.read()
  File "env/lib/python3.11/site-packages/pymysql/connections.py", line 1157, in read
    first_packet = self.connection._read_packet()
                   ^^^^^^^^^^^^^^^^^^^^^^^^^^^^^^
  File "env/lib/python3.11/site-packages/pymysql/connections.py", line 729, in _read_packet
    packet.raise_for_error()
  File "env/lib/python3.11/site-packages/pymysql/protocol.py", line 221, in raise_for_error
    err.raise_mysql_exception(self._data)
  File "env/lib/python3.11/site-packages/pymysql/err.py", line 143, in raise_mysql_exception
    raise errorclass(errno, errval)
pymysql.err.ProgrammingError: (1146, "Table '_3f14d08a0477f193.tabSingles' doesn't exist")

